Workbook

Sheet DASHBOARD
B2: PAINT PRINT | C2: PAINT PRINT | D2: PAINT PRINT | E2: PAINT PRINT | F2: PAINT PRINT | G2: PAINT PRINT | H2: PAINT PRINT | I2: PAINT PRINT
B3: Sistema de Costos, Inventario y Produccion | C3: Sistema de Costos, Inventario y Produccion | D3: Sistema de Costos, Inventario y Produccion | E3: Sistema de Costos, Inventario y Produccion | F3: Sistema de Costos, Inventario y Produccion | G3: Sistema de Costos, Inventario y Produccion | H3: Sistema de Costos, Inventario y Produccion | I3: Sistema de Costos, Inventario y Produccion
B4: Tu Idea, Nuestra Inspiracion | C4: Tu Idea, Nuestra Inspiracion | D4: Tu Idea, Nuestra Inspiracion | E4: Tu Idea, Nuestra Inspiracion | F4: Tu Idea, Nuestra Inspiracion | G4: Tu Idea, Nuestra Inspiracion | H4: Tu Idea, Nuestra Inspiracion | I4: Tu Idea, Nuestra Inspiracion
B6: MODULOS DEL SISTEMA — Haz clic para navegar a cada hoja | C6: MODULOS DEL SISTEMA — Haz clic para navegar a cada hoja | D6: MODULOS DEL SISTEMA — Haz clic para navegar a cada hoja | E6: MODULOS DEL SISTEMA — Haz clic para navegar a cada hoja | F6: MODULOS DEL SISTEMA — Haz clic para navegar a cada hoja | G6: MODULOS DEL SISTEMA — Haz clic para navegar a cada hoja | H6: MODULOS DEL SISTEMA — Haz clic para navegar a cada hoja | I6: MODULOS DEL SISTEMA — Haz clic para navegar a cada hoja
B8: =HYPERLINK("#CONFIGURACION!A1","CONFIGURACION") -> CONFIGURACION | C8: CONFIGURACION | D8: =HYPERLINK("#MATERIALES!A1","MATERIALES") -> MATERIALES | E8: MATERIALES | F8: =HYPERLINK("#RECETAS!A1","RECETAS") -> RECETAS | G8: RECETAS | H8: =HYPERLINK("#PRODUCTOS!A1","PRODUCTOS") -> PRODUCTOS | I8: PRODUCTOS
B10: =HYPERLINK("#VENTAS!A1","VENTAS") -> VENTAS | C10: VENTAS | D10: =HYPERLINK("#MOVIMIENTOS!A1","MOVIMIENTOS") -> MOVIMIENTOS | E10: MOVIMIENTOS | F10: =HYPERLINK("#REPORTES!A1","REPORTES") -> REPORTES | G10: REPORTES
B12: FLUJO DE TRABAJO DIARIO | C12: FLUJO DE TRABAJO DIARIO | D12: FLUJO DE TRABAJO DIARIO | E12: FLUJO DE TRABAJO DIARIO | F12: FLUJO DE TRABAJO DIARIO | G12: FLUJO DE TRABAJO DIARIO | H12: FLUJO DE TRABAJO DIARIO | I12: FLUJO DE TRABAJO DIARIO
B13: =HYPERLINK("#CONFIGURACION!A1","PASO 1") -> PASO 1 | C13: CONFIGURACION — Define tarifas, margenes y gastos fijos del negocio | D13: CONFIGURACION — Define tarifas, margenes y gastos fijos del negocio | E13: CONFIGURACION — Define tarifas, margenes y gastos fijos del negocio | F13: CONFIGURACION — Define tarifas, margenes y gastos fijos del negocio | G13: CONFIGURACION — Define tarifas, margenes y gastos fijos del negocio | H13: CONFIGURACION — Define tarifas, margenes y gastos fijos del negocio | I13: CONFIGURACION — Define tarifas, margenes y gastos fijos del negocio
B14: =HYPERLINK("#MATERIALES!A1","PASO 2") -> PASO 2 | C14: MATERIALES — Registra cada insumo con costo, cantidad y unidad de medida | D14: MATERIALES — Registra cada insumo con costo, cantidad y unidad de medida | E14: MATERIALES — Registra cada insumo con costo, cantidad y unidad de medida | F14: MATERIALES — Registra cada insumo con costo, cantidad y unidad de medida | G14: MATERIALES — Registra cada insumo con costo, cantidad y unidad de medida | H14: MATERIALES — Registra cada insumo con costo, cantidad y unidad de medida | I14: MATERIALES — Registra cada insumo con costo, cantidad y unidad de medida
B15: =HYPERLINK("#RECETAS!A1","PASO 3") -> PASO 3 | C15: RECETAS — Crea la formula de cada producto con sus materiales | D15: RECETAS — Crea la formula de cada producto con sus materiales | E15: RECETAS — Crea la formula de cada producto con sus materiales | F15: RECETAS — Crea la formula de cada producto con sus materiales | G15: RECETAS — Crea la formula de cada producto con sus materiales | H15: RECETAS — Crea la formula de cada producto con sus materiales | I15: RECETAS — Crea la formula de cada producto con sus materiales
B16: =HYPERLINK("#VENTAS!A1","PASO 4") -> PASO 4 | C16: VENTAS — Anota cada venta — el costo se calcula automaticamente | D16: VENTAS — Anota cada venta — el costo se calcula automaticamente | E16: VENTAS — Anota cada venta — el costo se calcula automaticamente | F16: VENTAS — Anota cada venta — el costo se calcula automaticamente | G16: VENTAS — Anota cada venta — el costo se calcula automaticamente | H16: VENTAS — Anota cada venta — el costo se calcula automaticamente | I16: VENTAS — Anota cada venta — el costo se calcula automaticamente
B17: =HYPERLINK("#MOVIMIENTOS!A1","PASO 5") -> PASO 5 | C17: MOVIMIENTOS — Controla entradas y salidas de stock en tiempo real | D17: MOVIMIENTOS — Controla entradas y salidas de stock en tiempo real | E17: MOVIMIENTOS — Controla entradas y salidas de stock en tiempo real | F17: MOVIMIENTOS — Controla entradas y salidas de stock en tiempo real | G17: MOVIMIENTOS — Controla entradas y salidas de stock en tiempo real | H17: MOVIMIENTOS — Controla entradas y salidas de stock en tiempo real | I17: MOVIMIENTOS — Controla entradas y salidas de stock en tiempo real
B19: GUIA DE COLORES | C19: GUIA DE COLORES | D19: GUIA DE COLORES | E19: GUIA DE COLORES | F19: GUIA DE COLORES | G19: GUIA DE COLORES | H19: GUIA DE COLORES | I19: GUIA DE COLORES
B20: AZUL | C20: Celdas editables — Aqui ingresas tus datos | D20: Celdas editables — Aqui ingresas tus datos | E20: Celdas editables — Aqui ingresas tus datos | F20: Celdas editables — Aqui ingresas tus datos | G20: Celdas editables — Aqui ingresas tus datos | H20: Celdas editables — Aqui ingresas tus datos | I20: Celdas editables — Aqui ingresas tus datos
B21: VERDE | C21: Formulas automaticas — NO modificar, el sistema calcula | D21: Formulas automaticas — NO modificar, el sistema calcula | E21: Formulas automaticas — NO modificar, el sistema calcula | F21: Formulas automaticas — NO modificar, el sistema calcula | G21: Formulas automaticas — NO modificar, el sistema calcula | H21: Formulas automaticas — NO modificar, el sistema calcula | I21: Formulas automaticas — NO modificar, el sistema calcula
B22: AMARILLO | C22: Alerta de inventario — Revisa y repone tu stock | D22: Alerta de inventario — Revisa y repone tu stock | E22: Alerta de inventario — Revisa y repone tu stock | F22: Alerta de inventario — Revisa y repone tu stock | G22: Alerta de inventario — Revisa y repone tu stock | H22: Alerta de inventario — Revisa y repone tu stock | I22: Alerta de inventario — Revisa y repone tu stock
B24: ACCESO RAPIDO A CARPETAS | C24: ACCESO RAPIDO A CARPETAS | D24: ACCESO RAPIDO A CARPETAS | E24: ACCESO RAPIDO A CARPETAS | F24: ACCESO RAPIDO A CARPETAS | G24: ACCESO RAPIDO A CARPETAS | H24: ACCESO RAPIDO A CARPETAS | I24: ACCESO RAPIDO A CARPETAS
B25: Ecosistema Jefferson — C:\Users\PC Francks\Desktop\ECOSISTEMA-JEFFERSON\ | C25: Ecosistema Jefferson — C:\Users\PC Francks\Desktop\ECOSISTEMA-JEFFERSON\ | D25: Ecosistema Jefferson — C:\Users\PC Francks\Desktop\ECOSISTEMA-JEFFERSON\ | E25: Ecosistema Jefferson — C:\Users\PC Francks\Desktop\ECOSISTEMA-JEFFERSON\ | F25: Ecosistema Jefferson — C:\Users\PC Francks\Desktop\ECOSISTEMA-JEFFERSON\ | G25: Ecosistema Jefferson — C:\Users\PC Francks\Desktop\ECOSISTEMA-JEFFERSON\ | H25: Ecosistema Jefferson — C:\Users\PC Francks\Desktop\ECOSISTEMA-JEFFERSON\ | I25: Ecosistema Jefferson — C:\Users\PC Francks\Desktop\ECOSISTEMA-JEFFERSON\
B26: Paint Print — C:\Users\PC Francks\Desktop\ECOSISTEMA-JEFFERSON\EMPRESAS\PAINT-PRINT\ | C26: Paint Print — C:\Users\PC Francks\Desktop\ECOSISTEMA-JEFFERSON\EMPRESAS\PAINT-PRINT\ | D26: Paint Print — C:\Users\PC Francks\Desktop\ECOSISTEMA-JEFFERSON\EMPRESAS\PAINT-PRINT\ | E26: Paint Print — C:\Users\PC Francks\Desktop\ECOSISTEMA-JEFFERSON\EMPRESAS\PAINT-PRINT\ | F26: Paint Print — C:\Users\PC Francks\Desktop\ECOSISTEMA-JEFFERSON\EMPRESAS\PAINT-PRINT\ | G26: Paint Print — C:\Users\PC Francks\Desktop\ECOSISTEMA-JEFFERSON\EMPRESAS\PAINT-PRINT\ | H26: Paint Print — C:\Users\PC Francks\Desktop\ECOSISTEMA-JEFFERSON\EMPRESAS\PAINT-PRINT\ | I26: Paint Print — C:\Users\PC Francks\Desktop\ECOSISTEMA-JEFFERSON\EMPRESAS\PAINT-PRINT\

Sheet CONFIGURACION
A1: PAINT PRINT -- CONFIGURACION DEL SISTEMA | F1: =HYPERLINK("#DASHBOARD!A1","Volver al Menu Principal") -> Volver al Menu Principal
A2: Modifica solo los valores en columna B (azul). | Contrasena de proteccion: paintprint
A4: PARAMETRO | B4: VALOR | C4: DESCRIPCION
A5: Valor hora de trabajo $ | B5: 4000 | C5: CLP por hora. Cambia aqui y todos los costos se actualizan.
A6: Margen minimo % | B6: 0.3 | C6: 30% -- Precio mas bajo posible. Por debajo de este precio pierdes.
A7: Margen recomendado % | B7: 0.55 | C7: 55% -- Precio justo. Cubre todo y genera utilidad real.
A8: Margen ideal % | B8: 0.7 | C8: 70% -- Precio premium. Para productos de alta demanda o exclusivos.
A9: Gastos fijos % sobre costo | B9: 0.15 | C9: 15% -- Electricidad, desgaste maquinas, internet, etc.
A10: Moneda | B10: CLP | C10: Peso chileno. Todos los precios y costos en CLP.
A12: LISTAS DE REFERENCIA -- uso interno del sistema (no borrar)
A13: UNIDAD_COMPRA | B13: UNIDAD_CONSUMO | C13: CATEGORIA | D13: ESTADO_PEDIDO | E13: TIPO_MOV | F13: CANAL_VENTA | G13: UNIDAD_VENTA
A14: pack | B14: unidad | C14: Papel y cartulina | D14: Cotizado | E14: ENTRADA | F14: Instagram | G14: pieza
A15: metro | B15: hoja | C15: Vinil | D15: Aprobado | E15: SALIDA | F15: WhatsApp | G15: set 10u
A16: litro | B16: metro | C16: Tinta e insumos | D16: En produccion | E16: MERMA | F16: Referido | G16: set 20u
A17: rollo | B17: centimetro | C17: Adhesivos | D17: Entregado | E17: AJUSTE | F17: Directo | G17: set 50u
A18: frasco | B18: cm2 | C18: Gran formato | D18: Pagado | F18: Feria | G18: set 100u
A19: caja | B19: ml | C19: Textil | D19: Archivado | F19: TikTok | G19: metro
A20: unidad | B20: gramo | C20: Madera y plastico | F20: Otro | G20: par
A21: hoja | B21: uso | C21: Otros | G21: Kit
A22: set | B22: rollo
A23: saco
A24: resma

Sheet MATERIALES
A1: PAINT PRINT -- CONTROL DE MATERIALES E INVENTARIO | E1: =HYPERLINK("#DASHBOARD!A1","Volver al Menu Principal") -> Volver al Menu Principal
A2: AZUL = Ingresa tu dato | VERDE = Formula automatica (no modificar) | Contrasena para desproteger: paintprint
A3: EQUIV. CONSUMO = cuantas unidades de consumo trae cada unidad de compra (ej: 1 pack = 20 hojas -> 20)
A4: ID | B4: MATERIAL | C4: CATEGORIA | D4: UNID. COMPRA | E4: EQUIV. CONSUMO | F4: UNID. CONSUMO | G4: CANT. COMPRADA | H4: COSTO TOTAL $ | I4: COSTO / UNID $ | J4: STOCK INICIAL | K4: ENTRADAS | L4: SALIDAS | M4: STOCK ACTUAL | N4: STOCK MINIMO | AO4: ALERTA | AP4: VALOR INV $ | AQ4: PROVEEDOR | AR4: FECHA COMPRA
A5: MP-001 | B5: Papel fotografico 260g | C5: Papel y cartulina | D5: pack | E5: 20 | F5: hoja | G5: 1 | H5: 5000 | I5: =IFERROR(H5/(G5*E5),0) -> 250 | J5: 100 | K5: =IFERROR(SUMIFS(MOVIMIENTOS!$E:$E,MOVIMIENTOS!$C:$C,$A5,MOVIMIENTOS!$B:$B,"ENTRADA"),0) -> 100 | L5: =IFERROR(SUMIFS(MOVIMIENTOS!$E:$E,MOVIMIENTOS!$C:$C,$A5,MOVIMIENTOS!$B:$B,"SALIDA")+SUMIFS(MOVIMIENTOS!$E:$E,MOVIMIENTOS!$C:$C,$A5,MOVIMIENTOS!$B:$B,"MERMA"),0) -> 0 | M5: =IFERROR(J5+K5-L5,0) -> 200 | N5: 20 | O5: =IF(M5<=N5,"REPONER","OK") -> OK | P5: =IFERROR(M5*I5,0) -> 50000 | AO5: =IF(M5<=N5,"REPONER","OK") -> OK | AP5: =IFERROR(M5*I5,0) -> 50000 | AQ5: Papeleria Central | AR5: 46195
A6: MP-002 | B6: Papel fotografico 180g | C6: Papel y cartulina | D6: pack | E6: 50 | F6: hoja | G6: 1 | H6: 3500 | I6: =IFERROR(H6/(G6*E6),0) -> 70 | J6: 100 | K6: =IFERROR(SUMIFS(MOVIMIENTOS!$E:$E,MOVIMIENTOS!$C:$C,$A6,MOVIMIENTOS!$B:$B,"ENTRADA"),0) -> 100 | L6: =IFERROR(SUMIFS(MOVIMIENTOS!$E:$E,MOVIMIENTOS!$C:$C,$A6,MOVIMIENTOS!$B:$B,"SALIDA")+SUMIFS(MOVIMIENTOS!$E:$E,MOVIMIENTOS!$C:$C,$A6,MOVIMIENTOS!$B:$B,"MERMA"),0) -> 0 | M6: =IFERROR(J6+K6-L6,0) -> 200 | N6: 20 | O6: =IF(M6<=N6,"REPONER","OK") -> OK | P6: =IFERROR(M6*I6,0) -> 14000 | AO6: =IF(M6<=N6,"REPONER","OK") -> OK | AP6: =IFERROR(M6*I6,0) -> 14000 | AQ6: Papeleria Central | AR6: 46195
A7: MP-003 | B7: Vinil imprimible (pack 20u) | C7: Vinil | D7: pack | E7: 20 | F7: hoja | G7: 1 | H7: 8000 | I7: =IFERROR(H7/(G7*E7),0) -> 400 | J7: 40 | K7: =IFERROR(SUMIFS(MOVIMIENTOS!$E:$E,MOVIMIENTOS!$C:$C,$A7,MOVIMIENTOS!$B:$B,"ENTRADA"),0) -> 40 | L7: =IFERROR(SUMIFS(MOVIMIENTOS!$E:$E,MOVIMIENTOS!$C:$C,$A7,MOVIMIENTOS!$B:$B,"SALIDA")+SUMIFS(MOVIMIENTOS!$E:$E,MOVIMIENTOS!$C:$C,$A7,MOVIMIENTOS!$B:$B,"MERMA"),0) -> 0 | M7: =IFERROR(J7+K7-L7,0) -> 80 | N7: 10 | O7: =IF(M7<=N7,"REPONER","OK") -> OK | P7: =IFERROR(M7*I7,0) -> 32000 | AO7: =IF(M7<=N7,"REPONER","OK") -> OK | AP7: =IFERROR(M7*I7,0) -> 32000 | AQ7: Insumos Graficos | AR7: 46195
A8: MP-004 | B8: Vinil textil por metro | C8: Textil | D8: metro | E8: 100 | F8: centimetro | G8: 1 | H8: 6000 | I8: =IFERROR(H8/(G8*E8),0) -> 60 | J8: 500 | K8: =IFERROR(SUMIFS(MOVIMIENTOS!$E:$E,MOVIMIENTOS!$C:$C,$A8,MOVIMIENTOS!$B:$B,"ENTRADA"),0) -> 500 | L8: =IFERROR(SUMIFS(MOVIMIENTOS!$E:$E,MOVIMIENTOS!$C:$C,$A8,MOVIMIENTOS!$B:$B,"SALIDA")+SUMIFS(MOVIMIENTOS!$E:$E,MOVIMIENTOS!$C:$C,$A8,MOVIMIENTOS!$B:$B,"MERMA"),0) -> 0 | M8: =IFERROR(J8+K8-L8,0) -> 1000 | N8: 200 | O8: =IF(M8<=N8,"REPONER","OK") -> OK | P8: =IFERROR(M8*I8,0) -> 60000 | AO8: =IF(M8<=N8,"REPONER","OK") -> OK | AP8: =IFERROR(M8*I8,0) -> 60000 | AQ8: Textiles Graficos | AR8: 46195
A9: MP-005 | B9: Papel adhesivo | C9: Papel y cartulina | D9: pack | E9: 25 | F9: hoja | G9: 1 | H9: 4500 | I9: =IFERROR(H9/(G9*E9),0) -> 180 | J9: 50 | K9: =IFERROR(SUMIFS(MOVIMIENTOS!$E:$E,MOVIMIENTOS!$C:$C,$A9,MOVIMIENTOS!$B:$B,"ENTRADA"),0) -> 50 | L9: =IFERROR(SUMIFS(MOVIMIENTOS!$E:$E,MOVIMIENTOS!$C:$C,$A9,MOVIMIENTOS!$B:$B,"SALIDA")+SUMIFS(MOVIMIENTOS!$E:$E,MOVIMIENTOS!$C:$C,$A9,MOVIMIENTOS!$B:$B,"MERMA"),0) -> 0 | M9: =IFERROR(J9+K9-L9,0) -> 100 | N9: 10 | O9: =IF(M9<=N9,"REPONER","OK") -> OK | P9: =IFERROR(M9*I9,0) -> 18000 | AO9: =IF(M9<=N9,"REPONER","OK") -> OK | AP9: =IFERROR(M9*I9,0) -> 18000 | AQ9: Papeleria Central | AR9: 46195
A10: MP-006 | B10: Cartulina opalina | C10: Papel y cartulina | D10: pack | E10: 20 | F10: hoja | G10: 1 | H10: 3000 | I10: =IFERROR(H10/(G10*E10),0) -> 150 | J10: 40 | K10: =IFERROR(SUMIFS(MOVIMIENTOS!$E:$E,MOVIMIENTOS!$C:$C,$A10,MOVIMIENTOS!$B:$B,"ENTRADA"),0) -> 40 | L10: =IFERROR(SUMIFS(MOVIMIENTOS!$E:$E,MOVIMIENTOS!$C:$C,$A10,MOVIMIENTOS!$B:$B,"SALIDA")+SUMIFS(MOVIMIENTOS!$E:$E,MOVIMIENTOS!$C:$C,$A10,MOVIMIENTOS!$B:$B,"MERMA"),0) -> 0 | M10: =IFERROR(J10+K10-L10,0) -> 80 | N10: 10 | O10: =IF(M10<=N10,"REPONER","OK") -> OK | P10: =IFERROR(M10*I10,0) -> 12000 | AO10: =IF(M10<=N10,"REPONER","OK") -> OK | AP10: =IFERROR(M10*I10,0) -> 12000 | AQ10: Papeleria Central | AR10: 46195
A11: MP-007 | B11: Pegamento | C11: Adhesivos | D11: frasco | E11: 50 | F11: uso | G11: 1 | H11: 2500 | I11: =IFERROR(H11/(G11*E11),0) -> 50 | J11: 3 | K11: =IFERROR(SUMIFS(MOVIMIENTOS!$E:$E,MOVIMIENTOS!$C:$C,$A11,MOVIMIENTOS!$B:$B,"ENTRADA"),0) -> 3 | L11: =IFERROR(SUMIFS(MOVIMIENTOS!$E:$E,MOVIMIENTOS!$C:$C,$A11,MOVIMIENTOS!$B:$B,"SALIDA")+SUMIFS(MOVIMIENTOS!$E:$E,MOVIMIENTOS!$C:$C,$A11,MOVIMIENTOS!$B:$B,"MERMA"),0) -> 0 | M11: =IFERROR(J11+K11-L11,0) -> 6 | N11: 1 | O11: =IF(M11<=N11,"REPONER","OK") -> OK | P11: =IFERROR(M11*I11,0) -> 300 | AO11: =IF(M11<=N11,"REPONER","OK") -> OK | AP11: =IFERROR(M11*I11,0) -> 300 | AQ11: Ferreteria Local | AR11: 46195
A12: MP-008 | B12: Palitos para toppers | C12: Otros | D12: pack | E12: 100 | F12: unidad | G12: 1 | H12: 1500 | I12: =IFERROR(H12/(G12*E12),0) -> 15 | J12: 200 | K12: =IFERROR(SUMIFS(MOVIMIENTOS!$E:$E,MOVIMIENTOS!$C:$C,$A12,MOVIMIENTOS!$B:$B,"ENTRADA"),0) -> 200 | L12: =IFERROR(SUMIFS(MOVIMIENTOS!$E:$E,MOVIMIENTOS!$C:$C,$A12,MOVIMIENTOS!$B:$B,"SALIDA")+SUMIFS(MOVIMIENTOS!$E:$E,MOVIMIENTOS!$C:$C,$A12,MOVIMIENTOS!$B:$B,"MERMA"),0) -> 0 | M12: =IFERROR(J12+K12-L12,0) -> 400 | N12: 50 | O12: =IF(M12<=N12,"REPONER","OK") -> OK | P12: =IFERROR(M12*I12,0) -> 6000 | AO12: =IF(M12<=N12,"REPONER","OK") -> OK | AP12: =IFERROR(M12*I12,0) -> 6000 | AQ12: Cotillon Center | AR12: 46195
A13: MP-009 | B13: Tinta Epson (set completo) | C13: Tinta e insumos | D13: set | E13: 200 | F13: uso | G13: 1 | H13: 35000 | I13: =IFERROR(H13/(G13*E13),0) -> 175 | J13: 400 | K13: =IFERROR(SUMIFS(MOVIMIENTOS!$E:$E,MOVIMIENTOS!$C:$C,$A13,MOVIMIENTOS!$B:$B,"ENTRADA"),0) -> 400 | L13: =IFERROR(SUMIFS(MOVIMIENTOS!$E:$E,MOVIMIENTOS!$C:$C,$A13,MOVIMIENTOS!$B:$B,"SALIDA")+SUMIFS(MOVIMIENTOS!$E:$E,MOVIMIENTOS!$C:$C,$A13,MOVIMIENTOS!$B:$B,"MERMA"),0) -> 0 | M13: =IFERROR(J13+K13-L13,0) -> 800 | N13: 100 | O13: =IF(M13<=N13,"REPONER","OK") -> OK | P13: =IFERROR(M13*I13,0) -> 140000 | AO13: =IF(M13<=N13,"REPONER","OK") -> OK | AP13: =IFERROR(M13*I13,0) -> 140000 | AQ13: Epson Chile | AR13: 46195
A14: MP-010 | B14: Lona para pendones | C14: Gran formato | D14: rollo | E14: 50000 | F14: cm2 | G14: 1 | H14: 40000 | I14: =IFERROR(H14/(G14*E14),0) -> 0.8 | J14: 50000 | K14: =IFERROR(SUMIFS(MOVIMIENTOS!$E:$E,MOVIMIENTOS!$C:$C,$A14,MOVIMIENTOS!$B:$B,"ENTRADA"),0) -> 50000 | L14: =IFERROR(SUMIFS(MOVIMIENTOS!$E:$E,MOVIMIENTOS!$C:$C,$A14,MOVIMIENTOS!$B:$B,"SALIDA")+SUMIFS(MOVIMIENTOS!$E:$E,MOVIMIENTOS!$C:$C,$A14,MOVIMIENTOS!$B:$B,"MERMA"),0) -> 0 | M14: =IFERROR(J14+K14-L14,0) -> 100000 | N14: 10000 | O14: =IF(M14<=N14,"REPONER","OK") -> OK | P14: =IFERROR(M14*I14,0) -> 80000 | AO14: =IF(M14<=N14,"REPONER","OK") -> OK | AP14: =IFERROR(M14*I14,0) -> 80000 | AQ14: Imprenta Mayorista | AR14: 46195
A15: MAT-TEST | B15: Material de Prueba | C15: PRUEBA | D15: kg | E15: 1 | F15: kg | G15: 10 | H15: 100 | I15: =IFERROR(H15/(G15*E15),0) -> 10 | J15: 8 | K15: =IFERROR(SUMIFS(MOVIMIENTOS!$E:$E,MOVIMIENTOS!$C:$C,$A15,MOVIMIENTOS!$B:$B,"ENTRADA"),0) -> 10 | L15: =IFERROR(SUMIFS(MOVIMIENTOS!$E:$E,MOVIMIENTOS!$C:$C,$A15,MOVIMIENTOS!$B:$B,"SALIDA")+SUMIFS(MOVIMIENTOS!$E:$E,MOVIMIENTOS!$C:$C,$A15,MOVIMIENTOS!$B:$B,"MERMA"),0) -> 0 | M15: =IFERROR(J15+K15-L15,0) -> 18 | N15: 2 | AO15: =IF(M15<=N15,"REPONER","OK") -> OK | AP15: =IFERROR(M15*I15,0) -> 180 | AQ15: Proveedor Test | AR15: 2026-06-26
I16: =IFERROR(H16/(G16*E16),0) -> 0 | K16: =IFERROR(SUMIFS(MOVIMIENTOS!$E:$E,MOVIMIENTOS!$C:$C,$A16,MOVIMIENTOS!$B:$B,"ENTRADA"),0) -> 0 | L16: =IFERROR(SUMIFS(MOVIMIENTOS!$E:$E,MOVIMIENTOS!$C:$C,$A16,MOVIMIENTOS!$B:$B,"SALIDA")+SUMIFS(MOVIMIENTOS!$E:$E,MOVIMIENTOS!$C:$C,$A16,MOVIMIENTOS!$B:$B,"MERMA"),0) -> 0 | M16: =IFERROR(J16+K16-L16,0) -> 0 | AO16: =IF(M16<=N16,"REPONER","OK") -> REPONER | AP16: =IFERROR(M16*I16,0) -> 0
I17: =IFERROR(H17/(G17*E17),0) -> 0 | K17: =IFERROR(SUMIFS(MOVIMIENTOS!$E:$E,MOVIMIENTOS!$C:$C,$A17,MOVIMIENTOS!$B:$B,"ENTRADA"),0) -> 0 | L17: =IFERROR(SUMIFS(MOVIMIENTOS!$E:$E,MOVIMIENTOS!$C:$C,$A17,MOVIMIENTOS!$B:$B,"SALIDA")+SUMIFS(MOVIMIENTOS!$E:$E,MOVIMIENTOS!$C:$C,$A17,MOVIMIENTOS!$B:$B,"MERMA"),0) -> 0 | M17: =IFERROR(J17+K17-L17,0) -> 0 | AO17: =IF(M17<=N17,"REPONER","OK") -> REPONER | AP17: =IFERROR(M17*I17,0) -> 0
I18: =IFERROR(H18/(G18*E18),0) -> 0 | K18: =IFERROR(SUMIFS(MOVIMIENTOS!$E:$E,MOVIMIENTOS!$C:$C,$A18,MOVIMIENTOS!$B:$B,"ENTRADA"),0) -> 0 | L18: =IFERROR(SUMIFS(MOVIMIENTOS!$E:$E,MOVIMIENTOS!$C:$C,$A18,MOVIMIENTOS!$B:$B,"SALIDA")+SUMIFS(MOVIMIENTOS!$E:$E,MOVIMIENTOS!$C:$C,$A18,MOVIMIENTOS!$B:$B,"MERMA"),0) -> 0 | M18: =IFERROR(J18+K18-L18,0) -> 0 | AO18: =IF(M18<=N18,"REPONER","OK") -> REPONER | AP18: =IFERROR(M18*I18,0) -> 0
I19: =IFERROR(H19/(G19*E19),0) -> 0 | K19: =IFERROR(SUMIFS(MOVIMIENTOS!$E:$E,MOVIMIENTOS!$C:$C,$A19,MOVIMIENTOS!$B:$B,"ENTRADA"),0) -> 0 | L19: =IFERROR(SUMIFS(MOVIMIENTOS!$E:$E,MOVIMIENTOS!$C:$C,$A19,MOVIMIENTOS!$B:$B,"SALIDA")+SUMIFS(MOVIMIENTOS!$E:$E,MOVIMIENTOS!$C:$C,$A19,MOVIMIENTOS!$B:$B,"MERMA"),0) -> 0 | M19: =IFERROR(J19+K19-L19,0) -> 0 | AO19: =IF(M19<=N19,"REPONER","OK") -> REPONER | AP19: =IFERROR(M19*I19,0) -> 0
I20: =IFERROR(H20/(G20*E20),0) -> 0 | K20: =IFERROR(SUMIFS(MOVIMIENTOS!$E:$E,MOVIMIENTOS!$C:$C,$A20,MOVIMIENTOS!$B:$B,"ENTRADA"),0) -> 0 | L20: =IFERROR(SUMIFS(MOVIMIENTOS!$E:$E,MOVIMIENTOS!$C:$C,$A20,MOVIMIENTOS!$B:$B,"SALIDA")+SUMIFS(MOVIMIENTOS!$E:$E,MOVIMIENTOS!$C:$C,$A20,MOVIMIENTOS!$B:$B,"MERMA"),0) -> 0 | M20: =IFERROR(J20+K20-L20,0) -> 0 | AO20: =IF(M20<=N20,"REPONER","OK") -> REPONER | AP20: =IFERROR(M20*I20,0) -> 0
I21: =IFERROR(H21/(G21*E21),0) -> 0 | K21: =IFERROR(SUMIFS(MOVIMIENTOS!$E:$E,MOVIMIENTOS!$C:$C,$A21,MOVIMIENTOS!$B:$B,"ENTRADA"),0) -> 0 | L21: =IFERROR(SUMIFS(MOVIMIENTOS!$E:$E,MOVIMIENTOS!$C:$C,$A21,MOVIMIENTOS!$B:$B,"SALIDA")+SUMIFS(MOVIMIENTOS!$E:$E,MOVIMIENTOS!$C:$C,$A21,MOVIMIENTOS!$B:$B,"MERMA"),0) -> 0 | M21: =IFERROR(J21+K21-L21,0) -> 0 | AO21: =IF(M21<=N21,"REPONER","OK") -> REPONER | AP21: =IFERROR(M21*I21,0) -> 0
I22: =IFERROR(H22/(G22*E22),0) -> 0 | K22: =IFERROR(SUMIFS(MOVIMIENTOS!$E:$E,MOVIMIENTOS!$C:$C,$A22,MOVIMIENTOS!$B:$B,"ENTRADA"),0) -> 0 | L22: =IFERROR(SUMIFS(MOVIMIENTOS!$E:$E,MOVIMIENTOS!$C:$C,$A22,MOVIMIENTOS!$B:$B,"SALIDA")+SUMIFS(MOVIMIENTOS!$E:$E,MOVIMIENTOS!$C:$C,$A22,MOVIMIENTOS!$B:$B,"MERMA"),0) -> 0 | M22: =IFERROR(J22+K22-L22,0) -> 0 | AO22: =IF(M22<=N22,"REPONER","OK") -> REPONER | AP22: =IFERROR(M22*I22,0) -> 0
I23: =IFERROR(H23/(G23*E23),0) -> 0 | K23: =IFERROR(SUMIFS(MOVIMIENTOS!$E:$E,MOVIMIENTOS!$C:$C,$A23,MOVIMIENTOS!$B:$B,"ENTRADA"),0) -> 0 | L23: =IFERROR(SUMIFS(MOVIMIENTOS!$E:$E,MOVIMIENTOS!$C:$C,$A23,MOVIMIENTOS!$B:$B,"SALIDA")+SUMIFS(MOVIMIENTOS!$E:$E,MOVIMIENTOS!$C:$C,$A23,MOVIMIENTOS!$B:$B,"MERMA"),0) -> 0 | M23: =IFERROR(J23+K23-L23,0) -> 0 | AO23: =IF(M23<=N23,"REPONER","OK") -> REPONER | AP23: =IFERROR(M23*I23,0) -> 0
I24: =IFERROR(H24/(G24*E24),0) -> 0 | K24: =IFERROR(SUMIFS(MOVIMIENTOS!$E:$E,MOVIMIENTOS!$C:$C,$A24,MOVIMIENTOS!$B:$B,"ENTRADA"),0) -> 0 | L24: =IFERROR(SUMIFS(MOVIMIENTOS!$E:$E,MOVIMIENTOS!$C:$C,$A24,MOVIMIENTOS!$B:$B,"SALIDA")+SUMIFS(MOVIMIENTOS!$E:$E,MOVIMIENTOS!$C:$C,$A24,MOVIMIENTOS!$B:$B,"MERMA"),0) -> 0 | M24: =IFERROR(J24+K24-L24,0) -> 0 | AO24: =IF(M24<=N24,"REPONER","OK") -> REPONER | AP24: =IFERROR(M24*I24,0) -> 0
I25: =IFERROR(H25/(G25*E25),0) -> 0 | K25: =IFERROR(SUMIFS(MOVIMIENTOS!$E:$E,MOVIMIENTOS!$C:$C,$A25,MOVIMIENTOS!$B:$B,"ENTRADA"),0) -> 0 | L25: =IFERROR(SUMIFS(MOVIMIENTOS!$E:$E,MOVIMIENTOS!$C:$C,$A25,MOVIMIENTOS!$B:$B,"SALIDA")+SUMIFS(MOVIMIENTOS!$E:$E,MOVIMIENTOS!$C:$C,$A25,MOVIMIENTOS!$B:$B,"MERMA"),0) -> 0 | M25: =IFERROR(J25+K25-L25,0) -> 0 | AO25: =IF(M25<=N25,"REPONER","OK") -> REPONER | AP25: =IFERROR(M25*I25,0) -> 0
I26: =IFERROR(H26/(G26*E26),0) -> 0 | K26: =IFERROR(SUMIFS(MOVIMIENTOS!$E:$E,MOVIMIENTOS!$C:$C,$A26,MOVIMIENTOS!$B:$B,"ENTRADA"),0) -> 0 | L26: =IFERROR(SUMIFS(MOVIMIENTOS!$E:$E,MOVIMIENTOS!$C:$C,$A26,MOVIMIENTOS!$B:$B,"SALIDA")+SUMIFS(MOVIMIENTOS!$E:$E,MOVIMIENTOS!$C:$C,$A26,MOVIMIENTOS!$B:$B,"MERMA"),0) -> 0 | M26: =IFERROR(J26+K26-L26,0) -> 0 | AO26: =IF(M26<=N26,"REPONER","OK") -> REPONER | AP26: =IFERROR(M26*I26,0) -> 0
I27: =IFERROR(H27/(G27*E27),0) -> 0 | K27: =IFERROR(SUMIFS(MOVIMIENTOS!$E:$E,MOVIMIENTOS!$C:$C,$A27,MOVIMIENTOS!$B:$B,"ENTRADA"),0) -> 0 | L27: =IFERROR(SUMIFS(MOVIMIENTOS!$E:$E,MOVIMIENTOS!$C:$C,$A27,MOVIMIENTOS!$B:$B,"SALIDA")+SUMIFS(MOVIMIENTOS!$E:$E,MOVIMIENTOS!$C:$C,$A27,MOVIMIENTOS!$B:$B,"MERMA"),0) -> 0 | M27: =IFERROR(J27+K27-L27,0) -> 0 | AO27: =IF(M27<=N27,"REPONER","OK") -> REPONER | AP27: =IFERROR(M27*I27,0) -> 0
... I300: =IFERROR(H300/(G300*E300),0) -> 0 | K300: =IFERROR(SUMIFS(MOVIMIENTOS!$E:$E,MOVIMIENTOS!$C:$C,$A300,MOVIMIENTOS!$B:$B,"ENTRADA"),0) -> 0 | L300: =IFERROR(SUMIFS(MOVIMIENTOS!$E:$E,MOVIMIENTOS!$C:$C,$A300,MOVIMIENTOS!$B:$B,"SALIDA")+SUMIFS(MOVIMIENTOS!$E:$E,MOVIMIENTOS!$C:$C,$A300,MOVIMIENTOS!$B:$B,"MERMA"),0) -> 0 | M300: =IFERROR(J300+K300-L300,0) -> 0 | AO300: =IF(M300<=N300,"REPONER","OK") -> REPONER | AP300: =IFERROR(M300*I300,0) -> 0

Sheet RECETAS
A1: PAINT PRINT -- RECETAS DE PRODUCTOS | E1: =HYPERLINK("#DASHBOARD!A1","Volver al Menu Principal") -> Volver al Menu Principal
A2: AZUL = Ingresa tu dato | VERDE = Formula automatica (no modificar) | Contrasena para desproteger: paintprint
A3: El nombre del producto en columna B debe existir exactamente igual en la hoja PRODUCTOS.
A4: ID RECETA | B4: PRODUCTO | C4: ID MATERIAL | D4: MATERIAL | E4: UNID. CONSUMO | F4: COSTO / UNID $ | G4: CANT. USADA | H4: SUBTOTAL $ | I4: NOTA
A5: R-TOP-01 | B5: Topper personalizado | C5: MP-001 | D5: =IFERROR(VLOOKUP(C5,MATERIALES!$A:$B,2,0),"") -> Papel fotografico 260g | E5: =IFERROR(VLOOKUP(C5,MATERIALES!$A:$F,6,0),"") -> hoja | F5: =IFERROR(VLOOKUP(C5,MATERIALES!$A:$I,9,0),0) -> 250 | G5: 0.5 | H5: =IFERROR(G5*F5,0) -> 125 | I5: Media hoja 260g por topper
A6: R-TOP-02 | B6: Topper personalizado | C6: MP-007 | D6: =IFERROR(VLOOKUP(C6,MATERIALES!$A:$B,2,0),"") -> Pegamento | E6: =IFERROR(VLOOKUP(C6,MATERIALES!$A:$F,6,0),"") -> uso | F6: =IFERROR(VLOOKUP(C6,MATERIALES!$A:$I,9,0),0) -> 50 | G6: 0.1 | H6: =IFERROR(G6*F6,0) -> 5 | I6: Pegamento para base
A7: R-TOP-03 | B7: Topper personalizado | C7: MP-008 | D7: =IFERROR(VLOOKUP(C7,MATERIALES!$A:$B,2,0),"") -> Palitos para toppers | E7: =IFERROR(VLOOKUP(C7,MATERIALES!$A:$F,6,0),"") -> unidad | F7: =IFERROR(VLOOKUP(C7,MATERIALES!$A:$I,9,0),0) -> 15 | G7: 2 | H7: =IFERROR(G7*F7,0) -> 30 | I7: 2 palitos por topper
A8: R-TOP-04 | B8: Topper personalizado | C8: MP-009 | D8: =IFERROR(VLOOKUP(C8,MATERIALES!$A:$B,2,0),"") -> Tinta Epson (set completo) | E8: =IFERROR(VLOOKUP(C8,MATERIALES!$A:$F,6,0),"") -> uso | F8: =IFERROR(VLOOKUP(C8,MATERIALES!$A:$I,9,0),0) -> 175 | G8: 0.3 | H8: =IFERROR(G8*F8,0) -> 52.5 | I8: Impresion color completa
A9: R-TAR-01 | B9: Tarjetas presentacion | C9: MP-002 | D9: =IFERROR(VLOOKUP(C9,MATERIALES!$A:$B,2,0),"") -> Papel fotografico 180g | E9: =IFERROR(VLOOKUP(C9,MATERIALES!$A:$F,6,0),"") -> hoja | F9: =IFERROR(VLOOKUP(C9,MATERIALES!$A:$I,9,0),0) -> 70 | G9: 9 | H9: =IFERROR(G9*F9,0) -> 630 | I9: 9 hojas para 100 tarjetas
A10: R-TAR-02 | B10: Tarjetas presentacion | C10: MP-009 | D10: =IFERROR(VLOOKUP(C10,MATERIALES!$A:$B,2,0),"") -> Tinta Epson (set completo) | E10: =IFERROR(VLOOKUP(C10,MATERIALES!$A:$F,6,0),"") -> uso | F10: =IFERROR(VLOOKUP(C10,MATERIALES!$A:$I,9,0),0) -> 175 | G10: 0.5 | H10: =IFERROR(G10*F10,0) -> 87.5 | I10: Impresion doble cara
A11: R-POL-01 | B11: Polera sublimada | C11: MP-004 | D11: =IFERROR(VLOOKUP(C11,MATERIALES!$A:$B,2,0),"") -> Vinil textil por metro | E11: =IFERROR(VLOOKUP(C11,MATERIALES!$A:$F,6,0),"") -> centimetro | F11: =IFERROR(VLOOKUP(C11,MATERIALES!$A:$I,9,0),0) -> 60 | G11: 60 | H11: =IFERROR(G11*F11,0) -> 3600 | I11: 60 cm vinil textil por polera
A12: R-POL-02 | B12: Polera sublimada | C12: MP-009 | D12: =IFERROR(VLOOKUP(C12,MATERIALES!$A:$B,2,0),"") -> Tinta Epson (set completo) | E12: =IFERROR(VLOOKUP(C12,MATERIALES!$A:$F,6,0),"") -> uso | F12: =IFERROR(VLOOKUP(C12,MATERIALES!$A:$I,9,0),0) -> 175 | G12: 0.2 | H12: =IFERROR(G12*F12,0) -> 35 | I12: Impresion transfer
A13: R-STI-01 | B13: Sticker personalizado | C13: MP-003 | D13: =IFERROR(VLOOKUP(C13,MATERIALES!$A:$B,2,0),"") -> Vinil imprimible (pack 20u) | E13: =IFERROR(VLOOKUP(C13,MATERIALES!$A:$F,6,0),"") -> hoja | F13: =IFERROR(VLOOKUP(C13,MATERIALES!$A:$I,9,0),0) -> 400 | G13: 1 | H13: =IFERROR(G13*F13,0) -> 400 | I13: 1 lamina vinil por set 20u
A14: R-STI-02 | B14: Sticker personalizado | C14: MP-009 | D14: =IFERROR(VLOOKUP(C14,MATERIALES!$A:$B,2,0),"") -> Tinta Epson (set completo) | E14: =IFERROR(VLOOKUP(C14,MATERIALES!$A:$F,6,0),"") -> uso | F14: =IFERROR(VLOOKUP(C14,MATERIALES!$A:$I,9,0),0) -> 175 | G14: 0.2 | H14: =IFERROR(G14*F14,0) -> 35 | I14: Impresion a color
A15: R-PEN-01 | B15: Pendon publicitario | C15: MP-010 | D15: =IFERROR(VLOOKUP(C15,MATERIALES!$A:$B,2,0),"") -> Lona para pendones | E15: =IFERROR(VLOOKUP(C15,MATERIALES!$A:$F,6,0),"") -> cm2 | F15: =IFERROR(VLOOKUP(C15,MATERIALES!$A:$I,9,0),0) -> 0.8 | G15: 9600 | H15: =IFERROR(G15*F15,0) -> 7680 | I15: 9600 cm2 por pendon 60x160
A16: R-PEN-02 | B16: Pendon publicitario | C16: MP-009 | D16: =IFERROR(VLOOKUP(C16,MATERIALES!$A:$B,2,0),"") -> Tinta Epson (set completo) | E16: =IFERROR(VLOOKUP(C16,MATERIALES!$A:$F,6,0),"") -> uso | F16: =IFERROR(VLOOKUP(C16,MATERIALES!$A:$I,9,0),0) -> 175 | G16: 0.5 | H16: =IFERROR(G16*F16,0) -> 87.5 | I16: Impresion gran formato
... A26: REC-TEST | B26: Producto de Prueba | C26: MAT-TEST | D26: =IFERROR(VLOOKUP(C26,MATERIALES!$A:$B,2,0),"") -> Material de Prueba | E26: =IFERROR(VLOOKUP(C26,MATERIALES!$A:$F,6,0),"") -> kg | F26: =IFERROR(VLOOKUP(C26,MATERIALES!$A:$I,9,0),0) -> 10 | G26: 0.5 | H26: =IFERROR(G26*F26,0) -> 5 | I26: Receta de prueba
D27: =IFERROR(VLOOKUP(C27,MATERIALES!$A:$B,2,0),"") | E27: =IFERROR(VLOOKUP(C27,MATERIALES!$A:$F,6,0),"") | F27: =IFERROR(VLOOKUP(C27,MATERIALES!$A:$I,9,0),0) -> 0 | H27: =IFERROR(G27*F27,0) -> 0
D28: =IFERROR(VLOOKUP(C28,MATERIALES!$A:$B,2,0),"") | E28: =IFERROR(VLOOKUP(C28,MATERIALES!$A:$F,6,0),"") | F28: =IFERROR(VLOOKUP(C28,MATERIALES!$A:$I,9,0),0) -> 0 | H28: =IFERROR(G28*F28,0) -> 0
D29: =IFERROR(VLOOKUP(C29,MATERIALES!$A:$B,2,0),"") | E29: =IFERROR(VLOOKUP(C29,MATERIALES!$A:$F,6,0),"") | F29: =IFERROR(VLOOKUP(C29,MATERIALES!$A:$I,9,0),0) -> 0 | H29: =IFERROR(G29*F29,0) -> 0
D30: =IFERROR(VLOOKUP(C30,MATERIALES!$A:$B,2,0),"") | E30: =IFERROR(VLOOKUP(C30,MATERIALES!$A:$F,6,0),"") | F30: =IFERROR(VLOOKUP(C30,MATERIALES!$A:$I,9,0),0) -> 0 | H30: =IFERROR(G30*F30,0) -> 0
D31: =IFERROR(VLOOKUP(C31,MATERIALES!$A:$B,2,0),"") | E31: =IFERROR(VLOOKUP(C31,MATERIALES!$A:$F,6,0),"") | F31: =IFERROR(VLOOKUP(C31,MATERIALES!$A:$I,9,0),0) -> 0 | H31: =IFERROR(G31*F31,0) -> 0
D32: =IFERROR(VLOOKUP(C32,MATERIALES!$A:$B,2,0),"") | E32: =IFERROR(VLOOKUP(C32,MATERIALES!$A:$F,6,0),"") | F32: =IFERROR(VLOOKUP(C32,MATERIALES!$A:$I,9,0),0) -> 0 | H32: =IFERROR(G32*F32,0) -> 0
D33: =IFERROR(VLOOKUP(C33,MATERIALES!$A:$B,2,0),"") | E33: =IFERROR(VLOOKUP(C33,MATERIALES!$A:$F,6,0),"") | F33: =IFERROR(VLOOKUP(C33,MATERIALES!$A:$I,9,0),0) -> 0 | H33: =IFERROR(G33*F33,0) -> 0
D34: =IFERROR(VLOOKUP(C34,MATERIALES!$A:$B,2,0),"") | E34: =IFERROR(VLOOKUP(C34,MATERIALES!$A:$F,6,0),"") | F34: =IFERROR(VLOOKUP(C34,MATERIALES!$A:$I,9,0),0) -> 0 | H34: =IFERROR(G34*F34,0) -> 0
D35: =IFERROR(VLOOKUP(C35,MATERIALES!$A:$B,2,0),"") | E35: =IFERROR(VLOOKUP(C35,MATERIALES!$A:$F,6,0),"") | F35: =IFERROR(VLOOKUP(C35,MATERIALES!$A:$I,9,0),0) -> 0 | H35: =IFERROR(G35*F35,0) -> 0
D36: =IFERROR(VLOOKUP(C36,MATERIALES!$A:$B,2,0),"") | E36: =IFERROR(VLOOKUP(C36,MATERIALES!$A:$F,6,0),"") | F36: =IFERROR(VLOOKUP(C36,MATERIALES!$A:$I,9,0),0) -> 0 | H36: =IFERROR(G36*F36,0) -> 0
D37: =IFERROR(VLOOKUP(C37,MATERIALES!$A:$B,2,0),"") | E37: =IFERROR(VLOOKUP(C37,MATERIALES!$A:$F,6,0),"") | F37: =IFERROR(VLOOKUP(C37,MATERIALES!$A:$I,9,0),0) -> 0 | H37: =IFERROR(G37*F37,0) -> 0
D38: =IFERROR(VLOOKUP(C38,MATERIALES!$A:$B,2,0),"") | E38: =IFERROR(VLOOKUP(C38,MATERIALES!$A:$F,6,0),"") | F38: =IFERROR(VLOOKUP(C38,MATERIALES!$A:$I,9,0),0) -> 0 | H38: =IFERROR(G38*F38,0) -> 0
... D300: =IFERROR(VLOOKUP(C300,MATERIALES!$A:$B,2,0),"") | E300: =IFERROR(VLOOKUP(C300,MATERIALES!$A:$F,6,0),"") | F300: =IFERROR(VLOOKUP(C300,MATERIALES!$A:$I,9,0),0) -> 0 | H300: =IFERROR(G300*F300,0) -> 0

Sheet PRODUCTOS
A1: PAINT PRINT -- CATALOGO Y COSTOS DE PRODUCTOS | E1: =HYPERLINK("#DASHBOARD!A1","Volver al Menu Principal") -> Volver al Menu Principal
A2: AZUL = Ingresa tu dato | VERDE = Formula automatica (no modificar) | Contrasena para desproteger: paintprint
A3: PRECIO MINIMO(30%) / PRECIO JUSTO(55%) / PRECIO IDEAL(70%) se calculan desde CONFIGURACION automaticamente.
A4: CODIGO | B4: PRODUCTO | C4: DESCRIPCION | D4: UNID. VENTA | E4: COSTO MAT $ | F4: MIN DIS | G4: MIN IMP | H4: MIN COR | I4: MIN ARM | J4: MIN TOTAL | K4: $/HORA | L4: COSTO MO $ | M4: % GF | N4: GASTOS FIJ $ | AO4: COSTO TOTAL $ | AP4: PRECIO MIN $ | AQ4: PRECIO JUSTO $ | AR4: PRECIO IDEAL $ | AS4: PRECIO ACTUAL $ | AT4: MARGEN ACT % | AU4: ESTADO
A5: PP-001 | B5: Topper personalizado | C5: Toppers para eventos y fiestas | D5: pieza | E5: =IFERROR(SUMIF(RECETAS!$B:$B,B5,RECETAS!$H:$H),0) -> 212.5 | F5: 5 | G5: 5 | H5: 0 | I5: 5 | J5: =F5+G5+H5+I5 -> 15 | K5: =IFERROR(CONFIGURACION!$B$5,0) -> 4000 | L5: =IFERROR(J5*K5/60,0) -> 1000 | M5: =IFERROR(CONFIGURACION!$B$9,0) -> 0.15 | N5: =IFERROR((E5+L5)*M5,0) -> 181.875 | O5: =IFERROR(E5+L5+N5,0) -> 1394.375 | P5: =IFERROR(ROUNDUP(O5/(1-CONFIGURACION!$B$6),0),0) -> 1992 | Q5: =IFERROR(ROUNDUP(O5/(1-CONFIGURACION!$B$7),0),0) -> 3099 | R5: =IFERROR(ROUNDUP(O5/(1-CONFIGURACION!$B$8),0),0) -> 4648 | S5: 6500 | T5: =IF(S5>0,(S5-O5)/S5,0) -> 0.78548077 | U5: =IF(S5=0,"SIN PRECIO",IF(T5<CONFIGURACION!$B$6,"BAJO COSTO",IF(T5<CONFIGURACION!$B$7,"REVISAR","OK"))) -> OK | AO5: =IFERROR(E5+L5+N5,0) -> 1394.375 | AP5: =IFERROR(ROUNDUP(O5/(1-CONFIGURACION!$B$6),0),0) -> 1992 | AQ5: =IFERROR(ROUNDUP(O5/(1-CONFIGURACION!$B$7),0),0) -> 3099 | AR5: =IFERROR(ROUNDUP(O5/(1-CONFIGURACION!$B$8),0),0) -> 4648 | AS5: 6500 | AT5: =IF(S5>0,(S5-O5)/S5,0) -> 0.78548077
A6: PP-002 | B6: Topper premium iluminado | C6: Topper con estructura y luz LED | D6: pieza | E6: =IFERROR(SUMIF(RECETAS!$B:$B,B6,RECETAS!$H:$H),0) -> 0 | F6: 8 | G6: 8 | H6: 0 | I6: 10 | J6: =F6+G6+H6+I6 -> 26 | K6: =IFERROR(CONFIGURACION!$B$5,0) -> 4000 | L6: =IFERROR(J6*K6/60,0) -> 1733.3333 | M6: =IFERROR(CONFIGURACION!$B$9,0) -> 0.15 | N6: =IFERROR((E6+L6)*M6,0) -> 260 | O6: =IFERROR(E6+L6+N6,0) -> 1993.3333 | P6: =IFERROR(ROUNDUP(O6/(1-CONFIGURACION!$B$6),0),0) -> 2848 | Q6: =IFERROR(ROUNDUP(O6/(1-CONFIGURACION!$B$7),0),0) -> 4430 | R6: =IFERROR(ROUNDUP(O6/(1-CONFIGURACION!$B$8),0),0) -> 6645 | S6: 22500 | T6: =IF(S6>0,(S6-O6)/S6,0) -> 0.91140741 | U6: =IF(S6=0,"SIN PRECIO",IF(T6<CONFIGURACION!$B$6,"BAJO COSTO",IF(T6<CONFIGURACION!$B$7,"REVISAR","OK"))) -> OK | AO6: =IFERROR(E6+L6+N6,0) -> 1993.3333 | AP6: =IFERROR(ROUNDUP(O6/(1-CONFIGURACION!$B$6),0),0) -> 2848 | AQ6: =IFERROR(ROUNDUP(O6/(1-CONFIGURACION!$B$7),0),0) -> 4430 | AR6: =IFERROR(ROUNDUP(O6/(1-CONFIGURACION!$B$8),0),0) -> 6645 | AS6: 22500 | AT6: =IF(S6>0,(S6-O6)/S6,0) -> 0.91140741
A7: PP-003 | B7: Tarjetas presentacion | C7: Set de 100 tarjetas impresas | D7: set 100u | E7: =IFERROR(SUMIF(RECETAS!$B:$B,B7,RECETAS!$H:$H),0) -> 717.5 | F7: 10 | G7: 10 | H7: 5 | I7: 2 | J7: =F7+G7+H7+I7 -> 27 | K7: =IFERROR(CONFIGURACION!$B$5,0) -> 4000 | L7: =IFERROR(J7*K7/60,0) -> 1800 | M7: =IFERROR(CONFIGURACION!$B$9,0) -> 0.15 | N7: =IFERROR((E7+L7)*M7,0) -> 377.625 | O7: =IFERROR(E7+L7+N7,0) -> 2895.125 | P7: =IFERROR(ROUNDUP(O7/(1-CONFIGURACION!$B$6),0),0) -> 4136 | Q7: =IFERROR(ROUNDUP(O7/(1-CONFIGURACION!$B$7),0),0) -> 6434 | R7: =IFERROR(ROUNDUP(O7/(1-CONFIGURACION!$B$8),0),0) -> 9651 | S7: 12500 | T7: =IF(S7>0,(S7-O7)/S7,0) -> 0.76839 | U7: =IF(S7=0,"SIN PRECIO",IF(T7<CONFIGURACION!$B$6,"BAJO COSTO",IF(T7<CONFIGURACION!$B$7,"REVISAR","OK"))) -> OK | AO7: =IFERROR(E7+L7+N7,0) -> 2895.125 | AP7: =IFERROR(ROUNDUP(O7/(1-CONFIGURACION!$B$6),0),0) -> 4136 | AQ7: =IFERROR(ROUNDUP(O7/(1-CONFIGURACION!$B$7),0),0) -> 6434 | AR7: =IFERROR(ROUNDUP(O7/(1-CONFIGURACION!$B$8),0),0) -> 9651 | AS7: 12500 | AT7: =IF(S7>0,(S7-O7)/S7,0) -> 0.76839
A8: PP-004 | B8: Flyer volante | C8: Impresion digital por unidad | D8: pieza | E8: =IFERROR(SUMIF(RECETAS!$B:$B,B8,RECETAS!$H:$H),0) -> 84 | F8: 3 | G8: 3 | H8: 0 | I8: 0 | J8: =F8+G8+H8+I8 -> 6 | K8: =IFERROR(CONFIGURACION!$B$5,0) -> 4000 | L8: =IFERROR(J8*K8/60,0) -> 400 | M8: =IFERROR(CONFIGURACION!$B$9,0) -> 0.15 | N8: =IFERROR((E8+L8)*M8,0) -> 72.6 | O8: =IFERROR(E8+L8+N8,0) -> 556.6 | P8: =IFERROR(ROUNDUP(O8/(1-CONFIGURACION!$B$6),0),0) -> 796 | Q8: =IFERROR(ROUNDUP(O8/(1-CONFIGURACION!$B$7),0),0) -> 1237 | R8: =IFERROR(ROUNDUP(O8/(1-CONFIGURACION!$B$8),0),0) -> 1856 | S8: 350 | T8: =IF(S8>0,(S8-O8)/S8,0) -> -0.59028571 | U8: =IF(S8=0,"SIN PRECIO",IF(T8<CONFIGURACION!$B$6,"BAJO COSTO",IF(T8<CONFIGURACION!$B$7,"REVISAR","OK"))) -> BAJO COSTO | AO8: =IFERROR(E8+L8+N8,0) -> 556.6 | AP8: =IFERROR(ROUNDUP(O8/(1-CONFIGURACION!$B$6),0),0) -> 796 | AQ8: =IFERROR(ROUNDUP(O8/(1-CONFIGURACION!$B$7),0),0) -> 1237 | AR8: =IFERROR(ROUNDUP(O8/(1-CONFIGURACION!$B$8),0),0) -> 1856 | AS8: 350 | AT8: =IF(S8>0,(S8-O8)/S8,0) -> -0.59028571
A9: PP-005 | B9: Etiqueta adhesiva | C9: Set 20 unidades personalizadas | D9: set 20u | E9: =IFERROR(SUMIF(RECETAS!$B:$B,B9,RECETAS!$H:$H),0) -> 386.25 | F9: 5 | G9: 5 | H9: 5 | I9: 0 | J9: =F9+G9+H9+I9 -> 15 | K9: =IFERROR(CONFIGURACION!$B$5,0) -> 4000 | L9: =IFERROR(J9*K9/60,0) -> 1000 | M9: =IFERROR(CONFIGURACION!$B$9,0) -> 0.15 | N9: =IFERROR((E9+L9)*M9,0) -> 207.9375 | O9: =IFERROR(E9+L9+N9,0) -> 1594.1875 | P9: =IFERROR(ROUNDUP(O9/(1-CONFIGURACION!$B$6),0),0) -> 2278 | Q9: =IFERROR(ROUNDUP(O9/(1-CONFIGURACION!$B$7),0),0) -> 3543 | R9: =IFERROR(ROUNDUP(O9/(1-CONFIGURACION!$B$8),0),0) -> 5314 | S9: 5500 | T9: =IF(S9>0,(S9-O9)/S9,0) -> 0.71014773 | U9: =IF(S9=0,"SIN PRECIO",IF(T9<CONFIGURACION!$B$6,"BAJO COSTO",IF(T9<CONFIGURACION!$B$7,"REVISAR","OK"))) -> OK | AO9: =IFERROR(E9+L9+N9,0) -> 1594.1875 | AP9: =IFERROR(ROUNDUP(O9/(1-CONFIGURACION!$B$6),0),0) -> 2278 | AQ9: =IFERROR(ROUNDUP(O9/(1-CONFIGURACION!$B$7),0),0) -> 3543 | AR9: =IFERROR(ROUNDUP(O9/(1-CONFIGURACION!$B$8),0),0) -> 5314 | AS9: 5500 | AT9: =IF(S9>0,(S9-O9)/S9,0) -> 0.71014773
A10: PP-006 | B10: Sticker personalizado | C10: Set 20 stickers con diseno | D10: set 20u | E10: =IFERROR(SUMIF(RECETAS!$B:$B,B10,RECETAS!$H:$H),0) -> 435 | F10: 5 | G10: 5 | H10: 5 | I10: 0 | J10: =F10+G10+H10+I10 -> 15 | K10: =IFERROR(CONFIGURACION!$B$5,0) -> 4000 | L10: =IFERROR(J10*K10/60,0) -> 1000 | M10: =IFERROR(CONFIGURACION!$B$9,0) -> 0.15 | N10: =IFERROR((E10+L10)*M10,0) -> 215.25 | O10: =IFERROR(E10+L10+N10,0) -> 1650.25 | P10: =IFERROR(ROUNDUP(O10/(1-CONFIGURACION!$B$6),0),0) -> 2358 | Q10: =IFERROR(ROUNDUP(O10/(1-CONFIGURACION!$B$7),0),0) -> 3668 | R10: =IFERROR(ROUNDUP(O10/(1-CONFIGURACION!$B$8),0),0) -> 5501 | S10: 4000 | T10: =IF(S10>0,(S10-O10)/S10,0) -> 0.5874375 | U10: =IF(S10=0,"SIN PRECIO",IF(T10<CONFIGURACION!$B$6,"BAJO COSTO",IF(T10<CONFIGURACION!$B$7,"REVISAR","OK"))) -> OK | AO10: =IFERROR(E10+L10+N10,0) -> 1650.25 | AP10: =IFERROR(ROUNDUP(O10/(1-CONFIGURACION!$B$6),0),0) -> 2358 | AQ10: =IFERROR(ROUNDUP(O10/(1-CONFIGURACION!$B$7),0),0) -> 3668 | AR10: =IFERROR(ROUNDUP(O10/(1-CONFIGURACION!$B$8),0),0) -> 5501 | AS10: 4000 | AT10: =IF(S10>0,(S10-O10)/S10,0) -> 0.5874375
A11: PP-007 | B11: Vinil personalizado | C11: Vinil cortado con diseno | D11: pieza | E11: =IFERROR(SUMIF(RECETAS!$B:$B,B11,RECETAS!$H:$H),0) -> 426.25 | F11: 10 | G11: 5 | H11: 10 | I11: 5 | J11: =F11+G11+H11+I11 -> 30 | K11: =IFERROR(CONFIGURACION!$B$5,0) -> 4000 | L11: =IFERROR(J11*K11/60,0) -> 2000 | M11: =IFERROR(CONFIGURACION!$B$9,0) -> 0.15 | N11: =IFERROR((E11+L11)*M11,0) -> 363.9375 | O11: =IFERROR(E11+L11+N11,0) -> 2790.1875 | P11: =IFERROR(ROUNDUP(O11/(1-CONFIGURACION!$B$6),0),0) -> 3986 | Q11: =IFERROR(ROUNDUP(O11/(1-CONFIGURACION!$B$7),0),0) -> 6201 | R11: =IFERROR(ROUNDUP(O11/(1-CONFIGURACION!$B$8),0),0) -> 9301 | S11: 9500 | T11: =IF(S11>0,(S11-O11)/S11,0) -> 0.70629605 | U11: =IF(S11=0,"SIN PRECIO",IF(T11<CONFIGURACION!$B$6,"BAJO COSTO",IF(T11<CONFIGURACION!$B$7,"REVISAR","OK"))) -> OK | AO11: =IFERROR(E11+L11+N11,0) -> 2790.1875 | AP11: =IFERROR(ROUNDUP(O11/(1-CONFIGURACION!$B$6),0),0) -> 3986 | AQ11: =IFERROR(ROUNDUP(O11/(1-CONFIGURACION!$B$7),0),0) -> 6201 | AR11: =IFERROR(ROUNDUP(O11/(1-CONFIGURACION!$B$8),0),0) -> 9301 | AS11: 9500 | AT11: =IF(S11>0,(S11-O11)/S11,0) -> 0.70629605
A12: PP-008 | B12: Polera sublimada | C12: Polera con diseno sublimado | D12: pieza | E12: =IFERROR(SUMIF(RECETAS!$B:$B,B12,RECETAS!$H:$H),0) -> 3635 | F12: 10 | G12: 8 | H12: 5 | I12: 7 | J12: =F12+G12+H12+I12 -> 30 | K12: =IFERROR(CONFIGURACION!$B$5,0) -> 4000 | L12: =IFERROR(J12*K12/60,0) -> 2000 | M12: =IFERROR(CONFIGURACION!$B$9,0) -> 0.15 | N12: =IFERROR((E12+L12)*M12,0) -> 845.25 | O12: =IFERROR(E12+L12+N12,0) -> 6480.25 | P12: =IFERROR(ROUNDUP(O12/(1-CONFIGURACION!$B$6),0),0) -> 9258 | Q12: =IFERROR(ROUNDUP(O12/(1-CONFIGURACION!$B$7),0),0) -> 14401 | R12: =IFERROR(ROUNDUP(O12/(1-CONFIGURACION!$B$8),0),0) -> 21601 | S12: 8500 | T12: =IF(S12>0,(S12-O12)/S12,0) -> 0.23761765 | U12: =IF(S12=0,"SIN PRECIO",IF(T12<CONFIGURACION!$B$6,"BAJO COSTO",IF(T12<CONFIGURACION!$B$7,"REVISAR","OK"))) -> BAJO COSTO | AO12: =IFERROR(E12+L12+N12,0) -> 6480.25 | AP12: =IFERROR(ROUNDUP(O12/(1-CONFIGURACION!$B$6),0),0) -> 9258 | AQ12: =IFERROR(ROUNDUP(O12/(1-CONFIGURACION!$B$7),0),0) -> 14401 | AR12: =IFERROR(ROUNDUP(O12/(1-CONFIGURACION!$B$8),0),0) -> 21601 | AS12: 8500 | AT12: =IF(S12>0,(S12-O12)/S12,0) -> 0.23761765
A13: PP-009 | B13: Pendon publicitario | C13: Pendon 60x160cm impreso | D13: pieza | E13: =IFERROR(SUMIF(RECETAS!$B:$B,B13,RECETAS!$H:$H),0) -> 7767.5 | F13: 15 | G13: 15 | H13: 0 | I13: 15 | J13: =F13+G13+H13+I13 -> 45 | K13: =IFERROR(CONFIGURACION!$B$5,0) -> 4000 | L13: =IFERROR(J13*K13/60,0) -> 3000 | M13: =IFERROR(CONFIGURACION!$B$9,0) -> 0.15 | N13: =IFERROR((E13+L13)*M13,0) -> 1615.125 | O13: =IFERROR(E13+L13+N13,0) -> 12382.625 | P13: =IFERROR(ROUNDUP(O13/(1-CONFIGURACION!$B$6),0),0) -> 17690 | Q13: =IFERROR(ROUNDUP(O13/(1-CONFIGURACION!$B$7),0),0) -> 27517 | R13: =IFERROR(ROUNDUP(O13/(1-CONFIGURACION!$B$8),0),0) -> 41276 | S13: 18000 | T13: =IF(S13>0,(S13-O13)/S13,0) -> 0.31207639 | U13: =IF(S13=0,"SIN PRECIO",IF(T13<CONFIGURACION!$B$6,"BAJO COSTO",IF(T13<CONFIGURACION!$B$7,"REVISAR","OK"))) -> REVISAR | AO13: =IFERROR(E13+L13+N13,0) -> 12382.625 | AP13: =IFERROR(ROUNDUP(O13/(1-CONFIGURACION!$B$6),0),0) -> 17690 | AQ13: =IFERROR(ROUNDUP(O13/(1-CONFIGURACION!$B$7),0),0) -> 27517 | AR13: =IFERROR(ROUNDUP(O13/(1-CONFIGURACION!$B$8),0),0) -> 41276 | AS13: 18000 | AT13: =IF(S13>0,(S13-O13)/S13,0) -> 0.31207639
A14: PP-010 | B14: Caja personalizada | C14: Caja troquelada con diseno | D14: pieza | E14: =IFERROR(SUMIF(RECETAS!$B:$B,B14,RECETAS!$H:$H),0) -> 325 | F14: 15 | G14: 5 | H14: 15 | I14: 10 | J14: =F14+G14+H14+I14 -> 45 | K14: =IFERROR(CONFIGURACION!$B$5,0) -> 4000 | L14: =IFERROR(J14*K14/60,0) -> 3000 | M14: =IFERROR(CONFIGURACION!$B$9,0) -> 0.15 | N14: =IFERROR((E14+L14)*M14,0) -> 498.75 | O14: =IFERROR(E14+L14+N14,0) -> 3823.75 | P14: =IFERROR(ROUNDUP(O14/(1-CONFIGURACION!$B$6),0),0) -> 5463 | Q14: =IFERROR(ROUNDUP(O14/(1-CONFIGURACION!$B$7),0),0) -> 8498 | R14: =IFERROR(ROUNDUP(O14/(1-CONFIGURACION!$B$8),0),0) -> 12746 | S14: 7500 | T14: =IF(S14>0,(S14-O14)/S14,0) -> 0.49016667 | U14: =IF(S14=0,"SIN PRECIO",IF(T14<CONFIGURACION!$B$6,"BAJO COSTO",IF(T14<CONFIGURACION!$B$7,"REVISAR","OK"))) -> REVISAR | AO14: =IFERROR(E14+L14+N14,0) -> 3823.75 | AP14: =IFERROR(ROUNDUP(O14/(1-CONFIGURACION!$B$6),0),0) -> 5463 | AQ14: =IFERROR(ROUNDUP(O14/(1-CONFIGURACION!$B$7),0),0) -> 8498 | AR14: =IFERROR(ROUNDUP(O14/(1-CONFIGURACION!$B$8),0),0) -> 12746 | AS14: 7500 | AT14: =IF(S14>0,(S14-O14)/S14,0) -> 0.49016667
A15: PROD-TEST | B15: Producto de Prueba | C15: Descripcion test | D15: unidad | E15: =IFERROR(SUMIF(RECETAS!$B:$B,B15,RECETAS!$H:$H),0) -> 5 | F15: 10 | G15: 5 | H15: 5 | I15: 10 | J15: =F15+G15+H15+I15 -> 30 | K15: =IFERROR(CONFIGURACION!$B$5,0) -> 4000 | L15: =IFERROR(J15*K15/60,0) -> 2000 | M15: =IFERROR(CONFIGURACION!$B$9,0) -> 0.15 | N15: =IFERROR((E15+L15)*M15,0) -> 300.75 | AO15: =IFERROR(E15+L15+N15,0) -> 2305.75 | AP15: =IFERROR(ROUNDUP(O15/(1-CONFIGURACION!$B$6),0),0) -> 0 | AQ15: =IFERROR(ROUNDUP(O15/(1-CONFIGURACION!$B$7),0),0) -> 0 | AR15: =IFERROR(ROUNDUP(O15/(1-CONFIGURACION!$B$8),0),0) -> 0 | AS15: 250 | AT15: =IF(S15>0,(S15-O15)/S15,0) -> 0
E16: =IFERROR(SUMIF(RECETAS!$B:$B,B16,RECETAS!$H:$H),0) -> 0 | J16: =F16+G16+H16+I16 -> 0 | K16: =IFERROR(CONFIGURACION!$B$5,0) -> 4000 | L16: =IFERROR(J16*K16/60,0) -> 0 | M16: =IFERROR(CONFIGURACION!$B$9,0) -> 0.15 | N16: =IFERROR((E16+L16)*M16,0) -> 0 | AO16: =IFERROR(E16+L16+N16,0) -> 0 | AP16: =IFERROR(ROUNDUP(O16/(1-CONFIGURACION!$B$6),0),0) -> 0 | AQ16: =IFERROR(ROUNDUP(O16/(1-CONFIGURACION!$B$7),0),0) -> 0 | AR16: =IFERROR(ROUNDUP(O16/(1-CONFIGURACION!$B$8),0),0) -> 0 | AT16: =IF(S16>0,(S16-O16)/S16,0) -> 0
E17: =IFERROR(SUMIF(RECETAS!$B:$B,B17,RECETAS!$H:$H),0) -> 0 | J17: =F17+G17+H17+I17 -> 0 | K17: =IFERROR(CONFIGURACION!$B$5,0) -> 4000 | L17: =IFERROR(J17*K17/60,0) -> 0 | M17: =IFERROR(CONFIGURACION!$B$9,0) -> 0.15 | N17: =IFERROR((E17+L17)*M17,0) -> 0 | AO17: =IFERROR(E17+L17+N17,0) -> 0 | AP17: =IFERROR(ROUNDUP(O17/(1-CONFIGURACION!$B$6),0),0) -> 0 | AQ17: =IFERROR(ROUNDUP(O17/(1-CONFIGURACION!$B$7),0),0) -> 0 | AR17: =IFERROR(ROUNDUP(O17/(1-CONFIGURACION!$B$8),0),0) -> 0 | AT17: =IF(S17>0,(S17-O17)/S17,0) -> 0
E18: =IFERROR(SUMIF(RECETAS!$B:$B,B18,RECETAS!$H:$H),0) -> 0 | J18: =F18+G18+H18+I18 -> 0 | K18: =IFERROR(CONFIGURACION!$B$5,0) -> 4000 | L18: =IFERROR(J18*K18/60,0) -> 0 | M18: =IFERROR(CONFIGURACION!$B$9,0) -> 0.15 | N18: =IFERROR((E18+L18)*M18,0) -> 0 | AO18: =IFERROR(E18+L18+N18,0) -> 0 | AP18: =IFERROR(ROUNDUP(O18/(1-CONFIGURACION!$B$6),0),0) -> 0 | AQ18: =IFERROR(ROUNDUP(O18/(1-CONFIGURACION!$B$7),0),0) -> 0 | AR18: =IFERROR(ROUNDUP(O18/(1-CONFIGURACION!$B$8),0),0) -> 0 | AT18: =IF(S18>0,(S18-O18)/S18,0) -> 0
E19: =IFERROR(SUMIF(RECETAS!$B:$B,B19,RECETAS!$H:$H),0) -> 0 | J19: =F19+G19+H19+I19 -> 0 | K19: =IFERROR(CONFIGURACION!$B$5,0) -> 4000 | L19: =IFERROR(J19*K19/60,0) -> 0 | M19: =IFERROR(CONFIGURACION!$B$9,0) -> 0.15 | N19: =IFERROR((E19+L19)*M19,0) -> 0 | AO19: =IFERROR(E19+L19+N19,0) -> 0 | AP19: =IFERROR(ROUNDUP(O19/(1-CONFIGURACION!$B$6),0),0) -> 0 | AQ19: =IFERROR(ROUNDUP(O19/(1-CONFIGURACION!$B$7),0),0) -> 0 | AR19: =IFERROR(ROUNDUP(O19/(1-CONFIGURACION!$B$8),0),0) -> 0 | AT19: =IF(S19>0,(S19-O19)/S19,0) -> 0
E20: =IFERROR(SUMIF(RECETAS!$B:$B,B20,RECETAS!$H:$H),0) -> 0 | J20: =F20+G20+H20+I20 -> 0 | K20: =IFERROR(CONFIGURACION!$B$5,0) -> 4000 | L20: =IFERROR(J20*K20/60,0) -> 0 | M20: =IFERROR(CONFIGURACION!$B$9,0) -> 0.15 | N20: =IFERROR((E20+L20)*M20,0) -> 0 | AO20: =IFERROR(E20+L20+N20,0) -> 0 | AP20: =IFERROR(ROUNDUP(O20/(1-CONFIGURACION!$B$6),0),0) -> 0 | AQ20: =IFERROR(ROUNDUP(O20/(1-CONFIGURACION!$B$7),0),0) -> 0 | AR20: =IFERROR(ROUNDUP(O20/(1-CONFIGURACION!$B$8),0),0) -> 0 | AT20: =IF(S20>0,(S20-O20)/S20,0) -> 0
E21: =IFERROR(SUMIF(RECETAS!$B:$B,B21,RECETAS!$H:$H),0) -> 0 | J21: =F21+G21+H21+I21 -> 0 | K21: =IFERROR(CONFIGURACION!$B$5,0) -> 4000 | L21: =IFERROR(J21*K21/60,0) -> 0 | M21: =IFERROR(CONFIGURACION!$B$9,0) -> 0.15 | N21: =IFERROR((E21+L21)*M21,0) -> 0 | AO21: =IFERROR(E21+L21+N21,0) -> 0 | AP21: =IFERROR(ROUNDUP(O21/(1-CONFIGURACION!$B$6),0),0) -> 0 | AQ21: =IFERROR(ROUNDUP(O21/(1-CONFIGURACION!$B$7),0),0) -> 0 | AR21: =IFERROR(ROUNDUP(O21/(1-CONFIGURACION!$B$8),0),0) -> 0 | AT21: =IF(S21>0,(S21-O21)/S21,0) -> 0
E22: =IFERROR(SUMIF(RECETAS!$B:$B,B22,RECETAS!$H:$H),0) -> 0 | J22: =F22+G22+H22+I22 -> 0 | K22: =IFERROR(CONFIGURACION!$B$5,0) -> 4000 | L22: =IFERROR(J22*K22/60,0) -> 0 | M22: =IFERROR(CONFIGURACION!$B$9,0) -> 0.15 | N22: =IFERROR((E22+L22)*M22,0) -> 0 | AO22: =IFERROR(E22+L22+N22,0) -> 0 | AP22: =IFERROR(ROUNDUP(O22/(1-CONFIGURACION!$B$6),0),0) -> 0 | AQ22: =IFERROR(ROUNDUP(O22/(1-CONFIGURACION!$B$7),0),0) -> 0 | AR22: =IFERROR(ROUNDUP(O22/(1-CONFIGURACION!$B$8),0),0) -> 0 | AT22: =IF(S22>0,(S22-O22)/S22,0) -> 0
E23: =IFERROR(SUMIF(RECETAS!$B:$B,B23,RECETAS!$H:$H),0) -> 0 | J23: =F23+G23+H23+I23 -> 0 | K23: =IFERROR(CONFIGURACION!$B$5,0) -> 4000 | L23: =IFERROR(J23*K23/60,0) -> 0 | M23: =IFERROR(CONFIGURACION!$B$9,0) -> 0.15 | N23: =IFERROR((E23+L23)*M23,0) -> 0 | AO23: =IFERROR(E23+L23+N23,0) -> 0 | AP23: =IFERROR(ROUNDUP(O23/(1-CONFIGURACION!$B$6),0),0) -> 0 | AQ23: =IFERROR(ROUNDUP(O23/(1-CONFIGURACION!$B$7),0),0) -> 0 | AR23: =IFERROR(ROUNDUP(O23/(1-CONFIGURACION!$B$8),0),0) -> 0 | AT23: =IF(S23>0,(S23-O23)/S23,0) -> 0
E24: =IFERROR(SUMIF(RECETAS!$B:$B,B24,RECETAS!$H:$H),0) -> 0 | J24: =F24+G24+H24+I24 -> 0 | K24: =IFERROR(CONFIGURACION!$B$5,0) -> 4000 | L24: =IFERROR(J24*K24/60,0) -> 0 | M24: =IFERROR(CONFIGURACION!$B$9,0) -> 0.15 | N24: =IFERROR((E24+L24)*M24,0) -> 0 | AO24: =IFERROR(E24+L24+N24,0) -> 0 | AP24: =IFERROR(ROUNDUP(O24/(1-CONFIGURACION!$B$6),0),0) -> 0 | AQ24: =IFERROR(ROUNDUP(O24/(1-CONFIGURACION!$B$7),0),0) -> 0 | AR24: =IFERROR(ROUNDUP(O24/(1-CONFIGURACION!$B$8),0),0) -> 0 | AT24: =IF(S24>0,(S24-O24)/S24,0) -> 0
E25: =IFERROR(SUMIF(RECETAS!$B:$B,B25,RECETAS!$H:$H),0) -> 0 | J25: =F25+G25+H25+I25 -> 0 | K25: =IFERROR(CONFIGURACION!$B$5,0) -> 4000 | L25: =IFERROR(J25*K25/60,0) -> 0 | M25: =IFERROR(CONFIGURACION!$B$9,0) -> 0.15 | N25: =IFERROR((E25+L25)*M25,0) -> 0 | AO25: =IFERROR(E25+L25+N25,0) -> 0 | AP25: =IFERROR(ROUNDUP(O25/(1-CONFIGURACION!$B$6),0),0) -> 0 | AQ25: =IFERROR(ROUNDUP(O25/(1-CONFIGURACION!$B$7),0),0) -> 0 | AR25: =IFERROR(ROUNDUP(O25/(1-CONFIGURACION!$B$8),0),0) -> 0 | AT25: =IF(S25>0,(S25-O25)/S25,0) -> 0
E26: =IFERROR(SUMIF(RECETAS!$B:$B,B26,RECETAS!$H:$H),0) -> 0 | J26: =F26+G26+H26+I26 -> 0 | K26: =IFERROR(CONFIGURACION!$B$5,0) -> 4000 | L26: =IFERROR(J26*K26/60,0) -> 0 | M26: =IFERROR(CONFIGURACION!$B$9,0) -> 0.15 | N26: =IFERROR((E26+L26)*M26,0) -> 0 | AO26: =IFERROR(E26+L26+N26,0) -> 0 | AP26: =IFERROR(ROUNDUP(O26/(1-CONFIGURACION!$B$6),0),0) -> 0 | AQ26: =IFERROR(ROUNDUP(O26/(1-CONFIGURACION!$B$7),0),0) -> 0 | AR26: =IFERROR(ROUNDUP(O26/(1-CONFIGURACION!$B$8),0),0) -> 0 | AT26: =IF(S26>0,(S26-O26)/S26,0) -> 0
E27: =IFERROR(SUMIF(RECETAS!$B:$B,B27,RECETAS!$H:$H),0) -> 0 | J27: =F27+G27+H27+I27 -> 0 | K27: =IFERROR(CONFIGURACION!$B$5,0) -> 4000 | L27: =IFERROR(J27*K27/60,0) -> 0 | M27: =IFERROR(CONFIGURACION!$B$9,0) -> 0.15 | N27: =IFERROR((E27+L27)*M27,0) -> 0 | AO27: =IFERROR(E27+L27+N27,0) -> 0 | AP27: =IFERROR(ROUNDUP(O27/(1-CONFIGURACION!$B$6),0),0) -> 0 | AQ27: =IFERROR(ROUNDUP(O27/(1-CONFIGURACION!$B$7),0),0) -> 0 | AR27: =IFERROR(ROUNDUP(O27/(1-CONFIGURACION!$B$8),0),0) -> 0 | AT27: =IF(S27>0,(S27-O27)/S27,0) -> 0
... E300: =IFERROR(SUMIF(RECETAS!$B:$B,B300,RECETAS!$H:$H),0) -> 0 | J300: =F300+G300+H300+I300 -> 0 | K300: =IFERROR(CONFIGURACION!$B$5,0) -> 4000 | L300: =IFERROR(J300*K300/60,0) -> 0 | M300: =IFERROR(CONFIGURACION!$B$9,0) -> 0.15 | N300: =IFERROR((E300+L300)*M300,0) -> 0 | AO300: =IFERROR(E300+L300+N300,0) -> 0 | AP300: =IFERROR(ROUNDUP(O300/(1-CONFIGURACION!$B$6),0),0) -> 0 | AQ300: =IFERROR(ROUNDUP(O300/(1-CONFIGURACION!$B$7),0),0) -> 0 | AR300: =IFERROR(ROUNDUP(O300/(1-CONFIGURACION!$B$8),0),0) -> 0 | AT300: =IF(S300>0,(S300-O300)/S300,0) -> 0

Sheet VENTAS
A1: PAINT PRINT -- REGISTRO DE VENTAS Y PEDIDOS | E1: =HYPERLINK("#DASHBOARD!A1","Volver al Menu Principal") -> Volver al Menu Principal
A2: AZUL = Ingresa tu dato | VERDE = Formula automatica (no modificar) | Contrasena para desproteger: paintprint
A3: Si el MARGEN es negativo o rojo -- el precio cobrado es menor que tu costo real.
A4: N PEDIDO | B4: FECHA | C4: CLIENTE | D4: PRODUCTO | E4: CANT. | F4: PRECIO COBRADO $ | G4: TOTAL VENTA $ | H4: COSTO UNIT $ | I4: COSTO TOTAL $ | J4: UTILIDAD $ | K4: MARGEN % | L4: MIN TRAB. | M4: GANANCIA/HORA $ | N4: CANAL | AO4: ESTADO | AP4: OBSERVACIONES
A5: P-001 | B5: 46195 | C5: Cliente Ejemplo | D5: Topper personalizado | E5: 10 | F5: 6500 | G5: =IFERROR(E5*F5,0) -> 65000 | H5: =IFERROR(VLOOKUP(D5,PRODUCTOS!$B:$O,14,0),0) -> 1394.375 | I5: =IFERROR(E5*H5,0) -> 13943.75 | J5: =IFERROR(G5-I5,0) -> 51056.25 | K5: =IF(G5>0,J5/G5,0) -> 0.78548077 | L5: 75 | M5: =IF(L5>0,J5/(L5/60),0) -> 40845 | N5: Instagram | AO5: Pagado | AP5: Pedido de ejemplo -- reemplazar con pedidos reales
A6: P-002 | C6: -- Agrega tu proximo pedido aqui -- | G6: =IFERROR(E6*F6,0) -> 0 | H6: =IFERROR(VLOOKUP(D6,PRODUCTOS!$B:$O,14,0),0) -> 0 | I6: =IFERROR(E6*H6,0) -> 0 | J6: =IFERROR(G6-I6,0) -> 0 | K6: =IF(G6>0,J6/G6,0) -> 0 | M6: =IF(L6>0,J6/(L6/60),0) -> 0
A105: TOTALES DEL MES | G105: =SUM(G5:G104) -> 65000 | I105: =SUM(I5:I104) -> 13943.75 | J105: =SUM(J5:J104) -> 51056.25 | K105: =IFERROR(J105/G105,0) -> 0.78548077
A106: PED-TEST | B106: 2026-06-26 | C106: Cliente Test | D106: Producto de Prueba | E106: 1 | F106: 250 | G106: =IFERROR(E106*F106,0) -> 250 | H106: =IFERROR(VLOOKUP(D106,PRODUCTOS!$B:$O,14,0),0) -> 0 | I106: =IFERROR(E106*H106,0) -> 0 | J106: =IFERROR(G106-I106,0) -> 250 | K106: =IF(G106>0,J106/G106,0) -> 1 | L106: 30 | M106: =IF(L106>0,J106/(L106/60),0) -> 500 | N106: ONLINE
G107: =IFERROR(E107*F107,0) -> 0 | H107: =IFERROR(VLOOKUP(D107,PRODUCTOS!$B:$O,14,0),0) -> 0 | I107: =IFERROR(E107*H107,0) -> 0 | J107: =IFERROR(G107-I107,0) -> 0 | K107: =IF(G107>0,J107/G107,0) -> 0 | M107: =IF(L107>0,J107/(L107/60),0) -> 0
G108: =IFERROR(E108*F108,0) -> 0 | H108: =IFERROR(VLOOKUP(D108,PRODUCTOS!$B:$O,14,0),0) -> 0 | I108: =IFERROR(E108*H108,0) -> 0 | J108: =IFERROR(G108-I108,0) -> 0 | K108: =IF(G108>0,J108/G108,0) -> 0 | M108: =IF(L108>0,J108/(L108/60),0) -> 0
G109: =IFERROR(E109*F109,0) -> 0 | H109: =IFERROR(VLOOKUP(D109,PRODUCTOS!$B:$O,14,0),0) -> 0 | I109: =IFERROR(E109*H109,0) -> 0 | J109: =IFERROR(G109-I109,0) -> 0 | K109: =IF(G109>0,J109/G109,0) -> 0 | M109: =IF(L109>0,J109/(L109/60),0) -> 0
G110: =IFERROR(E110*F110,0) -> 0 | H110: =IFERROR(VLOOKUP(D110,PRODUCTOS!$B:$O,14,0),0) -> 0 | I110: =IFERROR(E110*H110,0) -> 0 | J110: =IFERROR(G110-I110,0) -> 0 | K110: =IF(G110>0,J110/G110,0) -> 0 | M110: =IF(L110>0,J110/(L110/60),0) -> 0
G111: =IFERROR(E111*F111,0) -> 0 | H111: =IFERROR(VLOOKUP(D111,PRODUCTOS!$B:$O,14,0),0) -> 0 | I111: =IFERROR(E111*H111,0) -> 0 | J111: =IFERROR(G111-I111,0) -> 0 | K111: =IF(G111>0,J111/G111,0) -> 0 | M111: =IF(L111>0,J111/(L111/60),0) -> 0
G112: =IFERROR(E112*F112,0) -> 0 | H112: =IFERROR(VLOOKUP(D112,PRODUCTOS!$B:$O,14,0),0) -> 0 | I112: =IFERROR(E112*H112,0) -> 0 | J112: =IFERROR(G112-I112,0) -> 0 | K112: =IF(G112>0,J112/G112,0) -> 0 | M112: =IF(L112>0,J112/(L112/60),0) -> 0
G113: =IFERROR(E113*F113,0) -> 0 | H113: =IFERROR(VLOOKUP(D113,PRODUCTOS!$B:$O,14,0),0) -> 0 | I113: =IFERROR(E113*H113,0) -> 0 | J113: =IFERROR(G113-I113,0) -> 0 | K113: =IF(G113>0,J113/G113,0) -> 0 | M113: =IF(L113>0,J113/(L113/60),0) -> 0
G114: =IFERROR(E114*F114,0) -> 0 | H114: =IFERROR(VLOOKUP(D114,PRODUCTOS!$B:$O,14,0),0) -> 0 | I114: =IFERROR(E114*H114,0) -> 0 | J114: =IFERROR(G114-I114,0) -> 0 | K114: =IF(G114>0,J114/G114,0) -> 0 | M114: =IF(L114>0,J114/(L114/60),0) -> 0
G115: =IFERROR(E115*F115,0) -> 0 | H115: =IFERROR(VLOOKUP(D115,PRODUCTOS!$B:$O,14,0),0) -> 0 | I115: =IFERROR(E115*H115,0) -> 0 | J115: =IFERROR(G115-I115,0) -> 0 | K115: =IF(G115>0,J115/G115,0) -> 0 | M115: =IF(L115>0,J115/(L115/60),0) -> 0
G116: =IFERROR(E116*F116,0) -> 0 | H116: =IFERROR(VLOOKUP(D116,PRODUCTOS!$B:$O,14,0),0) -> 0 | I116: =IFERROR(E116*H116,0) -> 0 | J116: =IFERROR(G116-I116,0) -> 0 | K116: =IF(G116>0,J116/G116,0) -> 0 | M116: =IF(L116>0,J116/(L116/60),0) -> 0
G117: =IFERROR(E117*F117,0) -> 0 | H117: =IFERROR(VLOOKUP(D117,PRODUCTOS!$B:$O,14,0),0) -> 0 | I117: =IFERROR(E117*H117,0) -> 0 | J117: =IFERROR(G117-I117,0) -> 0 | K117: =IF(G117>0,J117/G117,0) -> 0 | M117: =IF(L117>0,J117/(L117/60),0) -> 0
G118: =IFERROR(E118*F118,0) -> 0 | H118: =IFERROR(VLOOKUP(D118,PRODUCTOS!$B:$O,14,0),0) -> 0 | I118: =IFERROR(E118*H118,0) -> 0 | J118: =IFERROR(G118-I118,0) -> 0 | K118: =IF(G118>0,J118/G118,0) -> 0 | M118: =IF(L118>0,J118/(L118/60),0) -> 0
... G300: =IFERROR(E300*F300,0) -> 0 | H300: =IFERROR(VLOOKUP(D300,PRODUCTOS!$B:$O,14,0),0) -> 0 | I300: =IFERROR(E300*H300,0) -> 0 | J300: =IFERROR(G300-I300,0) -> 0 | K300: =IF(G300>0,J300/G300,0) -> 0 | M300: =IF(L300>0,J300/(L300/60),0) -> 0

Sheet MOVIMIENTOS
A1: PAINT PRINT -- MOVIMIENTOS DE INVENTARIO | E1: =HYPERLINK("#DASHBOARD!A1","Volver al Menu Principal") -> Volver al Menu Principal
A2: AZUL = Ingresa tu dato | VERDE = Formula automatica (no modificar) | Contrasena para desproteger: paintprint
A3: TIPO: ENTRADA=compra | SALIDA=usado en produccion | MERMA=desperdicio | AJUSTE=correccion manual
A4: FECHA | B4: TIPO | C4: ID MATERIAL | D4: MATERIAL | E4: CANTIDAD | F4: UNIDAD | G4: COSTO/UNID $ | H4: VALOR MOV $ | I4: N PEDIDO REF | J4: NOTA
A5: 46195 | B5: ENTRADA | C5: MP-001 | D5: =IFERROR(VLOOKUP(C5,MATERIALES!$A:$B,2,0),"") -> Papel fotografico 260g | E5: 100 | F5: =IFERROR(VLOOKUP(C5,MATERIALES!$A:$F,6,0),"") -> hoja | G5: =IFERROR(VLOOKUP(C5,MATERIALES!$A:$I,9,0),0) -> 250 | H5: =IFERROR(E5*G5,0) -> 25000 | I5: STOCK INICIAL | J5: Stock inicial al comenzar el sistema
A6: 46195 | B6: ENTRADA | C6: MP-002 | D6: =IFERROR(VLOOKUP(C6,MATERIALES!$A:$B,2,0),"") -> Papel fotografico 180g | E6: 100 | F6: =IFERROR(VLOOKUP(C6,MATERIALES!$A:$F,6,0),"") -> hoja | G6: =IFERROR(VLOOKUP(C6,MATERIALES!$A:$I,9,0),0) -> 70 | H6: =IFERROR(E6*G6,0) -> 7000 | I6: STOCK INICIAL | J6: Stock inicial al comenzar el sistema
A7: 46195 | B7: ENTRADA | C7: MP-003 | D7: =IFERROR(VLOOKUP(C7,MATERIALES!$A:$B,2,0),"") -> Vinil imprimible (pack 20u) | E7: 40 | F7: =IFERROR(VLOOKUP(C7,MATERIALES!$A:$F,6,0),"") -> hoja | G7: =IFERROR(VLOOKUP(C7,MATERIALES!$A:$I,9,0),0) -> 400 | H7: =IFERROR(E7*G7,0) -> 16000 | I7: STOCK INICIAL | J7: Stock inicial al comenzar el sistema
A8: 46195 | B8: ENTRADA | C8: MP-004 | D8: =IFERROR(VLOOKUP(C8,MATERIALES!$A:$B,2,0),"") -> Vinil textil por metro | E8: 500 | F8: =IFERROR(VLOOKUP(C8,MATERIALES!$A:$F,6,0),"") -> centimetro | G8: =IFERROR(VLOOKUP(C8,MATERIALES!$A:$I,9,0),0) -> 60 | H8: =IFERROR(E8*G8,0) -> 30000 | I8: STOCK INICIAL | J8: Stock inicial al comenzar el sistema
A9: 46195 | B9: ENTRADA | C9: MP-005 | D9: =IFERROR(VLOOKUP(C9,MATERIALES!$A:$B,2,0),"") -> Papel adhesivo | E9: 50 | F9: =IFERROR(VLOOKUP(C9,MATERIALES!$A:$F,6,0),"") -> hoja | G9: =IFERROR(VLOOKUP(C9,MATERIALES!$A:$I,9,0),0) -> 180 | H9: =IFERROR(E9*G9,0) -> 9000 | I9: STOCK INICIAL | J9: Stock inicial al comenzar el sistema
A10: 46195 | B10: ENTRADA | C10: MP-006 | D10: =IFERROR(VLOOKUP(C10,MATERIALES!$A:$B,2,0),"") -> Cartulina opalina | E10: 40 | F10: =IFERROR(VLOOKUP(C10,MATERIALES!$A:$F,6,0),"") -> hoja | G10: =IFERROR(VLOOKUP(C10,MATERIALES!$A:$I,9,0),0) -> 150 | H10: =IFERROR(E10*G10,0) -> 6000 | I10: STOCK INICIAL | J10: Stock inicial al comenzar el sistema
A11: 46195 | B11: ENTRADA | C11: MP-007 | D11: =IFERROR(VLOOKUP(C11,MATERIALES!$A:$B,2,0),"") -> Pegamento | E11: 3 | F11: =IFERROR(VLOOKUP(C11,MATERIALES!$A:$F,6,0),"") -> uso | G11: =IFERROR(VLOOKUP(C11,MATERIALES!$A:$I,9,0),0) -> 50 | H11: =IFERROR(E11*G11,0) -> 150 | I11: STOCK INICIAL | J11: Stock inicial al comenzar el sistema
A12: 46195 | B12: ENTRADA | C12: MP-008 | D12: =IFERROR(VLOOKUP(C12,MATERIALES!$A:$B,2,0),"") -> Palitos para toppers | E12: 200 | F12: =IFERROR(VLOOKUP(C12,MATERIALES!$A:$F,6,0),"") -> unidad | G12: =IFERROR(VLOOKUP(C12,MATERIALES!$A:$I,9,0),0) -> 15 | H12: =IFERROR(E12*G12,0) -> 3000 | I12: STOCK INICIAL | J12: Stock inicial al comenzar el sistema
A13: 46195 | B13: ENTRADA | C13: MP-009 | D13: =IFERROR(VLOOKUP(C13,MATERIALES!$A:$B,2,0),"") -> Tinta Epson (set completo) | E13: 400 | F13: =IFERROR(VLOOKUP(C13,MATERIALES!$A:$F,6,0),"") -> uso | G13: =IFERROR(VLOOKUP(C13,MATERIALES!$A:$I,9,0),0) -> 175 | H13: =IFERROR(E13*G13,0) -> 70000 | I13: STOCK INICIAL | J13: Stock inicial al comenzar el sistema
A14: 46195 | B14: ENTRADA | C14: MP-010 | D14: =IFERROR(VLOOKUP(C14,MATERIALES!$A:$B,2,0),"") -> Lona para pendones | E14: 50000 | F14: =IFERROR(VLOOKUP(C14,MATERIALES!$A:$F,6,0),"") -> cm2 | G14: =IFERROR(VLOOKUP(C14,MATERIALES!$A:$I,9,0),0) -> 0.8 | H14: =IFERROR(E14*G14,0) -> 40000 | I14: STOCK INICIAL | J14: Stock inicial al comenzar el sistema
A15: 2026-06-26 | B15: ENTRADA | C15: MAT-TEST | D15: =IFERROR(VLOOKUP(C15,MATERIALES!$A:$B,2,0),"") -> Material de Prueba | E15: 10 | F15: =IFERROR(VLOOKUP(C15,MATERIALES!$A:$F,6,0),"") -> kg | G15: =IFERROR(VLOOKUP(C15,MATERIALES!$A:$I,9,0),0) -> 10 | H15: =IFERROR(E15*G15,0) -> 100 | I15: PED-TEST | J15: Movimiento de prueba
D16: =IFERROR(VLOOKUP(C16,MATERIALES!$A:$B,2,0),"") | F16: =IFERROR(VLOOKUP(C16,MATERIALES!$A:$F,6,0),"") | G16: =IFERROR(VLOOKUP(C16,MATERIALES!$A:$I,9,0),0) -> 0 | H16: =IFERROR(E16*G16,0) -> 0
D17: =IFERROR(VLOOKUP(C17,MATERIALES!$A:$B,2,0),"") | F17: =IFERROR(VLOOKUP(C17,MATERIALES!$A:$F,6,0),"") | G17: =IFERROR(VLOOKUP(C17,MATERIALES!$A:$I,9,0),0) -> 0 | H17: =IFERROR(E17*G17,0) -> 0
D18: =IFERROR(VLOOKUP(C18,MATERIALES!$A:$B,2,0),"") | F18: =IFERROR(VLOOKUP(C18,MATERIALES!$A:$F,6,0),"") | G18: =IFERROR(VLOOKUP(C18,MATERIALES!$A:$I,9,0),0) -> 0 | H18: =IFERROR(E18*G18,0) -> 0
D19: =IFERROR(VLOOKUP(C19,MATERIALES!$A:$B,2,0),"") | F19: =IFERROR(VLOOKUP(C19,MATERIALES!$A:$F,6,0),"") | G19: =IFERROR(VLOOKUP(C19,MATERIALES!$A:$I,9,0),0) -> 0 | H19: =IFERROR(E19*G19,0) -> 0
